Workbook

Sheet 修订历史
A1: 版本 | B1: 修订日期 | C1: 修订内容 | D1: 修订人
A2: V2021.1 | B2: 2021.1.26 | C2: 1、低压交流配电、低压直流配电的“所属机架位置”改为存在必填，汇聚及以上级别机房必填。 2、开关电源增加“所属机架位置”，存在必填，汇聚及以上级别机房必填。 3、增加了枚举值页面，供后续修订参考。 4、位置点动环属性增加“市电引入情况”、“是否下挂IDC机房”、“设计PUE”、“实际PUE”、“水冷机组配置情况”、“是否安装蓄冷罐”、“蓄冷时长”。 5、机房动环属性增加“空间专业机房类型”、“电池后备时间”、“供电模式”、“电源类型”、“空调末端”、“空调配置情况”、“制冷方式”、“参考PUE值”、“动环监控配置情况”、“视频监控配置情况”、“日志保存时长”。 6、低压交流配电“所属系统名称”改为存在必填。内容说明增加"关联到【UPS系统】-【系统名称】、【开关电源系统】-【系统名称】、【高压直流电源系统】-【系统名称】、【发电系统】-【系统名称】。 7、低压直流配电“所属系统名称”改为存在必填。所属系统名称可关联到【开关电源系统】-【系统名称】、【低压配电系统】-【系统名称】。 8、UPS设备“所属系统”改为存在必填。 9、动环专业内输出分路“下游设备类型”、“下游分路类型”、“下游分路类型缩写”、“下游分路顺序号”、“下游分路主备”、“下游使用状态”、“下游分路器件额定容量（A）”改为存在必填。 10、跨专业输出分路“下游设备类型”、“下游设备所在机架位置”、“下游机架内开关顺序号”、“下游负载加载功率”改为存在必填。 11、按动环资源命名规范修订各种设备示例名称。 12、机房动环属性的“电池后备时间”内容说明中增加“有OLT设备的机房必填”。 | D2: 王治法、刘勇及动环资源专家团队
A3: V2021.6 | B3: 2021.6.22 | C3: 1、“设备型号”、“设备厂家”字段增加枚举值，枚举表中进行了更新，设备厂家增加枚举值：北京中普瑞讯、其他。设备型号新增枚举值：ZP-BGA-8、DH120-10、ZP-RDUW-180、其他 2、低压直流配电、低压交流配电-所属机架位置的内容说明变更为：关联到【空间资源】-【机架位置】-资源标识。所属机房级别为： 汇聚（骨干、普通汇聚、综合业务接入）及以上（核心（省际）、核心（省内）、核心（本地））或者机房类型为：核心机房、IDC机房时；且设备子类为"列头柜"必填。 开关电源-所属机架位置的内容说明变更为：关联到【空间资源】-【机架位置】-资源标识。所属机房级别为： 汇聚（骨干、普通汇聚、综合业务接入）及以上（核心（省际）、核心（省内）、核心（本地））或者机房类型为：核心机房、IDC机房时为必填 3、高压直流配电“所属系统”改为存在必填。当所属机房类型为核心机房时必填。 | D3: 张亚静、刘勇、申鹏飞及动环资源专家团队
A4: v3 | B4: 2022.1 | C4: 1、站点动环属性模型增加字段“动环监控站点名称”； 2、机房动环属性模型增加字段“动环监控机房名称”； 3、修改低压交流配电模型“所属系统”字段内容说明，增加【低压配电系统】； 4、修改站点动环属性模型“蓄冷时长”字段内容说明，改为当“是否下挂IDC机房”为“是”时必填，"是否安装蓄冷罐"为"否"时可填0； 5、修改机房动环属性模型“空调末端”字段内容说明，增加“可多选，英文逗号分隔”； 6、修改机房动环属性模型“空间专业机房类型”字段类型为“关联型”，"动环专业机房类型"的内容说明改为“枚举参考powerRoomType"； 7、修改动环专业内输出分路、跨专业输出分路模型“使用状态”字段内容说明，改为“枚举参考deviceUseStatus 枚举值：在用、空闲”； 8、站点动环属性模型“产权单位”字段改为非必填，原因：该字段关联空间资源站点模型的产权单位字段，空间资源已删除该字段； 9、修改蓄电池模型设备子类； 10、其他设备模型增加设备类型&子类； 11、机房动环属性模型“供电模式”字段增加枚举值“其他”，字段说明进行相应修改； 12、修改高压配电系统、低压配电系统模型“系统额定容量(A)”字段中文名称为“系统额定容量(KVA)”，内容说明中单位修改为KVA； 13、修改空调模型“额定输入功率（W）”字段中文名称为“额定输入功率（KW）”，内容说明中单位修改为KW； 14、修改发电机组模型“所属系统”字段内容说明； 15、修改蓄电池模型“所属电源设备”内容说明，改为“关联到【UPS设备】、【开关电源】、【发电机组】、【高压直流电源】、【高压配电】中的资源标识”； 16、删除跨专业输出分路模型下游负载名称字段；新增下游设备所在机架字段；修改“所属设备类型”字段内容说明； 17、高压直流配电模型、动环监控模型增加设备子类； 18、修改站点动环属性“实际PUE”内容说明，改为“填写上一年PUE平均值（当“是否下挂IDC机房”为“是”时填写）”； 19、开关电源模型设备子类“分离高压直流电源”修改为“分立高压直流电源”； 20、其他设备模型增加字段“所属系统”字段； 21、节能设备模型增加设备类型&子类“潜热过渡”； 22、变压器、变换设备、高压配电、高压直流电源、高压直流配电、低压交流配电、发电机组、开关电源、低压直流配电、UPS设备、蓄电池、空调、节能设备、动环监控、智能电表、动环专业内输出分路、跨专业输出分路、其它设备模型增加“二维码编码”字段。 23、空调模型“额定制冷量（KW）”“额定输入功率（KW）”、节能设备模型“输入额定功率（KW）”字段类型修改为浮点型； 24、站点动环属性模型“市电总路数（路）”“市电容量（KVA）”“地下油罐总数量（个）”“地下油罐总容积（m³）”、机房动环属性模型“日志保存时长”、变压器模型“额定功率（KVA）”、变换设备模型“可装变换模块总数（块）”“实配变换模块总数（块）”“单个模块额定输出电流（A)”、高压配电系统模型“系统额定容量(KVA)”、高压配电模型“额定容量（A)”、高压直流电源系统模型“系统额定容量(A)”、高压直流电源模型“单个整流模块额定输出容量（A）”、高压直流配电模型“额定容量（A)”、低压配电系统模型“系统额定容量(KVA)”、低压交流配电模型“额定容量(A)”、发电系统模型“系统额定容量(KW)”、发电机组模型“额定功率（KW）”“额定输出电压（V)”、开关电源系统模型“系统额定容量(A)”、开关电源模型“单个整流模块额定输出容量（A）”低压直流配电模型“额定容量（A）”、UPS系统模型“系统额定容量(KVA)”、UPS设备模型“额定容量（KVA）”、蓄电池模型“额定容量（AH）”“组内单体总数（只）”、节能设备模型“额定制冷量（KW）”“系统总容量（W）”“系统输出电压（V）”“下挂风机额定功率（W）”“下挂太阳能组件额定容量（W）”“下挂太阳能组件额定容量（W）”、智能电表模型“电表回路数（路）”、动环专业内输出分路模型“分路器件额定容量（A）”“下游分路器件额定容量（A）”、跨专业输出分路模型“分路器件额定容量（A）”字段类型修改为整数型； 25、修改其他设备模型“额定容量”字段为存在必填； 26、修改变压器、变换设备模型“设备类型”、“设备子类”字段内容说明； 27、更新枚举值表； 28、各模型字段类型描述修改为中文； 29、修改节能设备模型“系统总容量（W）、系统输出电压（V）、下挂风机总数量（台）、下挂风机形式、下挂风机品牌、下挂风机额定功率（W）、下挂太阳能组件数（组）、下挂太阳能组件品牌、下挂太阳能组件额定容量（W）”字段为存在必填，修改内容说明； 30、低压交流配电模型增加设备子类“UPS并机柜” 31、高压配电模型增加设备子类“发电机输出柜”“高压油机接地柜”“二次设备”“三次设备”； 32、低压直流配电模型增加设备子类“UPS电池开关柜”。 33、空调模型设备类型为普通空调新增设备子类"VRV空调" | D4: 刘昕童、周浩及动环资源专家团队
A5: v3.1 | B5: 2022.6.14 | C5: 1、低压交流配电、低压直流配电的所属机架位置内容说明增加条件：“且空间专业机房类型机房类型不为动力机房”。开关电源的所属机架位置，改为非必填。 2、“设备类型&子类”中“开关电源”的子类“组合高压直流电源”“分立高压直流电源”删除。 3、在“低压交流配电、动环监控、蓄电池、UPS设备、开关电源、低压直流配电、发电机组、变压器、变换设备、智能电表、空调、其它设备、高压直流电源、高压直流配电、高压配电”模型中增加了“动环监控设备名称”和“动环监控设备ID”字段；在“站点动环属性”中添加“动环监控站点ID”字段；在“机房动环属性”中添加“动环监控机房ID”字段。 4、修改“高压直流电源系统”模型中“系统额定容量(A)”字段类型，由"整数型"更改为"整数型/浮点型"；修改“高压直流电源”模型中“单个整流模块额定输出容量（A）”字段类型，由"整数型"更改为"整数型/浮点型"。“跨专业输出分路”中“下游机架内开关顺序号”的字段类型，由字符型改成整数型。 5、删除了“高压直流电源系统、低压配电系统、发电系统、开关电源系统、UPS系统”模型中“资源系统类型”字段；删除了“动环专业内输出分路”和“跨专业输出分路”模型中“资源分路类型”字段。 | D5: 李宇晴、莫子凯、刘宏阳
A6: v3.2 | B6: 44736 | C6: 1、修订“专业类型”枚举值、新增跨专业输出分路中“下游设备类型”枚举值，删除冗余枚举表。 2、修改跨专业输出分路中“下游设备所在机房”、“下游设备类型”、“专业类型”为存在必填，当分路使用状态为在用时必填，存在多个时可以用英文逗号隔开填写。 3、修改“高压配电”模型中“所属系统”字段说明为：关联到【高压配电系统】或者【发电系统】-资源标识。 | D6: 李宇晴、莫子凯、刘宏阳
A7: v3.3 | B7: 44750 | C7: 1、设备类型&子类中“其他设备”表新增设备类型“一体化能源柜”“户外小型一体化电源”“交流母线配电”；“高压配电”的子类“操作电源”修改为“高压操作电源”。 | D7: 李宇晴、莫子凯、周浩
A8: V3.4 | B8: 44902 | C8: 1、新增“设备型号”“厂家”枚举值。 2、设备类型&子类中“机房专用空调”设备新增设备子类“恒湿机”、“加湿器”、“除湿器”； 设备类型&子类中“铅酸电池”设备新增设备子类“发电机组启动铅酸电池”； 设备类型&子类中“高压配电”设备新增设备子类“高压柜信号（控制）屏”； 设备类型&子类中“中央空调主机”设备新增设备子类“其他”； 设备类型&子类，“低压交流配电”设备新增设备子类“低压MTS切换柜”； 3、枚举值类型“所属设备类型/下游设备类型”的英文名由“linkDeviceType”更改为：“equipmentType/linkDeviceType”； 4、“站点动环属性”中的字段“市电容量（KVA）”的内容描述由（没有市电引入的位置点可不填写，数据中心和通信机楼必填，各路市电容量用英文逗号“;”隔开）更改为（没有市电引入的位置点可不填写，数据中心和通信机楼必填，各路市电容量用英文逗号“，”隔开）； 5、“高压直流配电”中的字段“所属系统”的内容描述由（所属机房类型为核心机房时必填；（关联）关联到【高压直流电源系统】-资源标识）更改为（所属站点的动环专业站点级别为数据中心或通信机楼必填；（关联）关联到【高压直流电源系统】-资源标识）； 6、枚举值类型“系统类型”下的枚举值“高压直流系统”更改为：“高压直流电源系统”。 | D8: 李宇晴、莫子凯、周浩
A9: V3.5 | B9: 45139 | C9: 1、“交流母线配电”设备类型、子类从【其他设备】改到【低压交流配电】模型下，交流母线配电中新增子类“始端箱”、“插接箱”。 2、在【UPS系统、UPS设备、开关电源系统、开关电源、高压直流电源系统、高压直流电源】中增加“是否5G关键网络设备”字段，在总部资管上用于标注为云平台资源池供电的电源系统及设备。（需求来源：工信部、监控室） 3、规范资产标签号字段，改为存在必填。 4、在【蓄电池】的“所属电源设备”的字段说明中增加“关联到【节能设备】的资源标识”。 **整合标准数据模型、最小集、同步模型。 | D9: 李宇晴
A10: V3.6 | B10: 45352 | C10: 1、【空调】的“设备子类“新增枚举值：空调-中央空调主机-RO纯水处理装置、定压补水装置、水泵、智能加药装置、蓄水池、蓄冷罐、分集水器、板式换热器；空调-中央空调末端-集中式冷板液冷空调CDU；（需求来源：内蒙古公司提出新增 液冷机柜） 2、【空调】的“额定工作电压（V）”新增枚举值：0。 3、【变压器】、【变换设备】、【高压配电】、【高压直流电源】、【低压交流配电】、【发电机组】、【开关电源】、【低压直流配电】、【UPS设备】、【蓄电池】、【空调】、【节能设备】、【动环监控】、【智能电表】的工程编号改为项目编码,所属工程改为项目名称，英文名称由“related_project”改为“project_name”,任务名称的英文名称由“task_name”改为“long_task_name”;【高压直流配电】、【其它设备】的工程编号改为项目编码,任务名称的英文名称由“task_name”改为“long_task_name”。 | D10: 李宇晴、苏莉、刘宏阳

Sheet 索引目录
A1: 编号 | B1: 资源模型名称 | C1: 资源模型英文名称 | D1: 链接 | E1: 标准模型数量 | F1: 部省同步模型数量 | G1: 最小集模型数量 | H1: 同步粒度
A2: 1 | B2: 站点动环属性 | C2: RM_SITE_PROPERTY | D2: 跳转 | E2: =COUNTA('1.站点动环属性'!B:B)-1 -> 25 | F2: =COUNTIF('1.站点动环属性'!I:I,"周粒度/日粒度") -> 24 | G2: =COUNTIF('1.站点动环属性'!K:K,"是") -> 24 | H2: 周粒度/日粒度
A3: 2 | B3: 机房动环属性 | C3: RM_ROOM_PROPERTY | D3: 跳转 | E3: =COUNTA('2.机房动环属性'!B:B)-1 -> 28 | F3: =COUNTIF('2.机房动环属性'!I:I,"周粒度/日粒度") -> 20 | G3: =COUNTIF('2.机房动环属性'!K:K,"是") -> 27 | H3: 周粒度/日粒度
A4: 3 | B4: 变压器 | C4: CE_DEVICE_PE_TRANSFORM | D4: 跳转 | E4: =COUNTA('3.变压器'!B:B)-1 -> 32 | F4: =COUNTIF('3.变压器'!I:I,"周粒度/日粒度") -> 26 | G4: =COUNTIF('3.变压器'!K:K,"是") -> 19 | H4: 周粒度/日粒度
A5: 4 | B5: 变换设备 | C5: CE_DECIVE_PE_TRANSFORM_DEVICE | D5: 跳转 | E5: =COUNTA('4.变换设备'!B:B)-1 -> 35 | F5: =COUNTIF('4.变换设备'!I:I,"周粒度") -> 28 | G5: =COUNTIF('4.变换设备'!K:K,"是") -> 23 | H5: 周粒度
A6: 5 | B6: 高压配电系统 | C6: CE_NET_PE_HIGH_DISTRIBUTION | D6: 跳转 | E6: =COUNTA('5.高压配电系统'!B:B)-1 -> 15 | F6: =COUNTIF('5.高压配电系统'!I:I,"周粒度") -> 13 | G6: =COUNTIF('5.高压配电系统'!K:K,"是") -> 8 | H6: 周粒度
A7: 6 | B7: 高压配电 | C7: CE_DEVICE_PE_HIGH_DISTRIBUTION | D7: 跳转 | E7: =COUNTA('6.高压配电'!B:B)-1 -> 31 | F7: =COUNTIF('6.高压配电'!I:I,"周粒度") -> 24 | G7: =COUNTIF('6.高压配电'!K:K,"是") -> 17 | H7: 周粒度
A8: 7 | B8: 高压直流电源系统 | C8: CE_NET_PE_HIGH_POWER | D8: 跳转 | E8: =COUNTA('7.高压直流电源系统'!B:B)-1 -> 15 | F8: =COUNTIF('7.高压直流电源系统'!I:I,"周粒度") -> 13 | G8: =COUNTIF('7.高压直流电源系统'!K:K,"是") -> 8 | H8: 周粒度
A9: 8 | B9: 高压直流电源 | C9: CE_DEVICE_PE_HIGH_POWER | D9: 跳转 | E9: =COUNTA('8.高压直流电源'!B:B)-1 -> 36 | F9: =COUNTIF('8.高压直流电源'!I:I,"周粒度") -> 28 | G9: =COUNTIF('8.高压直流电源'!K:K,"是") -> 22 | H9: 周粒度
A10: 9 | B10: 高压直流配电 | C10: CE_DEVICE_PE_HIGH_DC_DISTRIBUTION | D10: 跳转 | E10: =COUNTA('9.高压直流配电'!B:B)-1 -> 32 | F10: =COUNTIF('9.高压直流配电'!I:I,"周粒度") -> 26 | G10: =COUNTIF('9.高压直流配电'!K:K,"是") -> 19 | H10: 周粒度
A11: 10 | B11: 低压配电系统 | C11: CE_NET_PE_LOW_DISTRIBUTION | D11: 跳转 | E11: =COUNTA('10.低压配电系统'!B:B)-1 -> 17 | F11: =COUNTIF('10.低压配电系统'!I:I,"周粒度") -> 13 | G11: =COUNTIF('10.低压配电系统'!K:K,"是") -> 9 | H11: 周粒度
A12: 11 | B12: 低压交流配电 | C12: CE_DEVICE_PE_LOW_AC_DISTRIBUTION | D12: 跳转 | E12: =COUNTA('11.低压交流配电'!B:B)-1 -> 35 | F12: =COUNTIF('11.低压交流配电'!I:I,"周粒度") -> 29 | G12: =COUNTIF('11.低压交流配电'!K:K,"是") -> 21 | H12: 周粒度
A13: 12 | B13: 发电系统 | C13: CE_NET_PE_SWITCH_POWER | D13: 跳转 | E13: =COUNTA('12.发电系统'!B:B)-1 -> 15 | F13: =COUNTIF('12.发电系统'!I:I,"周粒度") -> 13 | G13: =COUNTIF('12.发电系统'!K:K,"是") -> 8 | H13: 周粒度
A14: 13 | B14: 发电机组 | C14: CE_DEVICE_PE_POWER_GENERATION | D14: 跳转 | E14: =COUNTA('13.发电机组'!B:B)-1 -> 39 | F14: =COUNTIF('13.发电机组'!I:I,"周粒度/日粒度") -> 30 | G14: =COUNTIF('13.发电机组'!K:K,"是") -> 26 | H14: 周粒度/日粒度
A15: 14 | B15: 开关电源系统 | C15: CE_NET_PE_OPEN_POWER | D15: 跳转 | E15: =COUNTA('14.开关电源系统'!B:B)-1 -> 15 | F15: =COUNTIF('14.开关电源系统'!I:I,"周粒度") -> 13 | G15: =COUNTIF('14.开关电源系统'!K:K,"是") -> 8 | H15: 周粒度
A16: 15 | B16: 开关电源 | C16: CE_DEVICE_PE_SWITCH_POWER | D16: 跳转 | E16: =COUNTA('15.开关电源'!B:B)-1 -> 36 | F16: =COUNTIF('15.开关电源'!I:I,"周粒度") -> 29 | G16: =COUNTIF('15.开关电源'!K:K,"是") -> 22 | H16: 周粒度
A17: 16 | B17: 低压直流配电 | C17: CE_DEVICE_PE_LOW_DC_DISTRIBUTION | D17: 跳转 | E17: =COUNTA('16.低压直流配电'!B:B)-1 -> 33 | F17: =COUNTIF('16.低压直流配电'!I:I,"周粒度") -> 27 | G17: =COUNTIF('16.低压直流配电'!K:K,"是") -> 19 | H17: 周粒度
A18: 17 | B18: UPS系统 | C18: CE_NET_PE_UPS | D18: 跳转 | E18: =COUNTA('17.UPS系统'!B:B)-1 -> 17 | F18: =COUNTIF('17.UPS系统'!I:I,"周粒度/日粒度") -> 15 | G18: =COUNTIF('17.UPS系统'!K:K,"是") -> 10 | H18: 周粒度/日粒度
A19: 18 | B19: UPS设备 | C19: CE_DEVICE_PE_UPS | D19: 跳转 | E19: =COUNTA('18.UPS设备'!B:B)-1 -> 36 | F19: =COUNTIF('18.UPS设备'!I:I,"周粒度") -> 25 | G19: =COUNTIF('18.UPS设备'!K:K,"是") -> 21 | H19: 周粒度
A20: 19 | B20: 蓄电池 | C20: CE_DEVICE_PE_BATTERY | D20: 跳转 | E20: =COUNTA('19.蓄电池'!B:B)-1 -> 33 | F20: =COUNTIF('19.蓄电池'!I:I,"周粒度") -> 27 | G20: =COUNTIF('19.蓄电池'!K:K,"是") -> 20 | H20: 周粒度
A21: 20 | B21: 空调 | C21: CE_DEVICE_PE_AIR | D21: 跳转 | E21: =COUNTA('20.空调'!B:B)-1 -> 33 | F21: =COUNTIF('20.空调'!I:I,"周粒度") -> 25 | G21: =COUNTIF('20.空调'!K:K,"是") -> 19 | H21: 周粒度
A22: 21 | B22: 节能设备 | C22: CE_DEVICE_PE_ENERY_SAVE | D22: 跳转 | E22: =COUNTA('21.节能设备'!B:B)-1 -> 40 | F22: =COUNTIF('21.节能设备'!I:I,"周粒度") -> 32 | G22: =COUNTIF('21.节能设备'!K:K,"是") -> 28 | H22: 周粒度
A23: 22 | B23: 动环监控 | C23: CE_DEVICE_PE_POWER_MONITOR | D23: 跳转 | E23: =COUNTA('22.动环监控'!B:B)-1 -> 28 | F23: =COUNTIF('22.动环监控'!I:I,"周粒度/日粒度") -> 22 | G23: =COUNTIF('22.动环监控'!K:K,"是") -> 15 | H23: 周粒度/日粒度
A24: 23 | B24: 智能电表 | C24: CE_DEVICE_PE_SMART_METER | D24: 跳转 | E24: =COUNTA('23.智能电表'!B:B)-1 -> 30 | F24: =COUNTIF('23.智能电表'!I:I,"周粒度") -> 23 | G24: =COUNTIF('23.智能电表'!K:K,"是") -> 17 | H24: 周粒度
A25: 24 | B25: 动环专业内输出分路 | C25: CE_LINK_PE_IN | D25: 跳转 | E25: =COUNTA('24.动环专业内输出分路'!B:B)-1 -> 27 | F25: =COUNTIF('24.动环专业内输出分路'!I:I,"周粒度") -> 27 | G25: =COUNTIF('24.动环专业内输出分路'!K:K,"是") -> 17 | H25: 周粒度
A26: 25 | B26: 跨专业输出分路 | C26: CE_LINK_PE_OUT | D26: 跳转 | E26: =COUNTA('25.跨专业输出分路'!B:B)-1 -> 25 | F26: =COUNTIF('25.跨专业输出分路'!I:I,"周粒度") -> 24 | G26: =COUNTIF('25.跨专业输出分路'!K:K,"是") -> 12 | H26: 周粒度
A27: 26 | B27: 其它设备 | C27: CE_DEVICE_PE_OTHER | D27: 跳转 | E27: =COUNTA('26.其它设备'!B:B)-1 -> 27 | F27: =COUNTIF('26.其它设备'!I:I,"周粒度") -> 24 | G27: =COUNTIF('26.其它设备'!K:K,"是") -> 23 | H27: 周粒度
A28: 合计 | E28: =SUM(E2:E27) -> 735 | F28: =SUM(F2:F27) -> 600 | G28: =SUM(G2:G27) -> 462

Sheet 枚举值
A1: DICT_CHN_NAME | B1: DICT_NAME | C1: DICT_KEY | D1: DICT_VALUE
A2: 动环专业站点级别 | B2: powerSiteLevel | C2: 0 | D2: 数据中心
A3: 动环专业站点级别 | B3: powerSiteLevel | C3: 1 | D3: 通信机楼
A4: 动环专业站点级别 | B4: powerSiteLevel | C4: 2 | D4: 传输节点
A5: 动环专业站点级别 | B5: powerSiteLevel | C5: 3 | D5: 通信基站
A6: 市电是否来自不同变电站 | B6: powerIsSubstations | C6: 0 | D6: 是
A7: 市电是否来自不同变电站 | B7: powerIsSubstations | C7: 1 | D7: 否
A8: 市电电压等级 | B8: mainsVoltageLevel | C8: 0 | D8: 10KV以上
A9: 市电电压等级 | B9: mainsVoltageLevel | C9: 1 | D9: 10KV
A10: 市电电压等级 | B10: mainsVoltageLevel | C10: 2 | D10: 380V
A11: 市电电压等级 | B11: mainsVoltageLevel | C11: 3 | D11: 220V
A12: 市电电压等级 | B12: mainsVoltageLevel | C12: 4 | D12: 无市电
A13: 市电性质 | B13: mainsNature | C13: 0 | D13: 市电转供
... A102: 额定工作电压（V） | B102: ratedOperatingVoltage | C102: 3 | D102: 10000V
A103: 额定工作电压（V） | B103: ratedOperatingVoltage | C103: 4 | D103: 0
A104: 下挂风机形式 | B104: fanForm | C104: 0 | D104: 水平轴
A105: 下挂风机形式 | B105: fanForm | C105: 1 | D105: 垂直轴
A106: 下挂风机形式 | B106: fanForm | C106: 2 | D106: 无
A107: 分路类型 | B107: branchType | C107: 0 | D107: 框架断路器
A108: 分路类型 | B108: branchType | C108: 1 | D108: 塑壳断路器
A109: 分路类型 | B109: branchType | C109: 2 | D109: 微型断路器
A110: 分路类型 | B110: branchType | C110: 3 | D110: 刀闸开关
A111: 分路类型 | B111: branchType | C111: 4 | D111: 熔断器
A112: 分路类型 | B112: branchType | C112: 5 | D112: 母排
A113: 分路类型 | B113: branchType | C113: 6 | D113: 设备
A114: 分路类型缩写 | B114: branchTypeAbbreviation | C114: 0 | D114: KOUT
A115: 分路类型缩写 | B115: branchTypeAbbreviation | C115: 1 | D115: ROUT
... A144: 系统类型 | B144: systemType | C144: 5 | D144: UPS系统
A145: 输入端口数（路） | B145: totalInputPort | C145: 0 | D145: 1
A146: 输入端口数（路） | B146: totalInputPort | C146: 1 | D146: 2
A147: 专业类型 | B147: majorType | C147: 0 | D147: 传输内线
A148: 专业类型 | B148: majorType | C148: 1 | D148: 核心网
A149: 专业类型 | B149: majorType | C149: 2 | D149: 家客
A150: 专业类型 | B150: majorType | C150: 3 | D150: 承载网
A151: 专业类型 | B151: majorType | C151: 4 | D151: 无线
A152: 专业类型 | B152: majorType | C152: 5 | D152: IDC
A153: 专业类型 | B153: majorType | C153: 6 | D153: 集客
A154: 专业类型 | B154: majorType | C154: 7 | D154: WLAN
A155: 专业类型 | B155: majorType | C155: 8 | D155: 网络云
A156: 专业类型 | B156: majorType | C156: 9 | D156: 内容网络
...

Sheet 设备类型&子类
A1: 表名 | B1: 设备类型 | C1: 设备子类
A2: 高压配电 | B2: 高压配电 | C2: 高压进线柜
C3: 高压计量柜
C4: 高压避雷器柜
C5: 高压隔离柜
C6: 高压升高柜
C7: 高压压变柜
C8: 高压母联柜
C9: 高压出线柜
C10: 高压电容补偿柜
C11: 高压油机配电柜
C12: 高压切换柜
C13: 高压操作电源
C14: 高压油机接地柜
... C18: 高压柜信号（控制）屏
A19: 低压交流配电 | B19: 低压交流配电 | C19: 低压进线柜
C20: 低压进线计量柜
C21: 低压计量柜
C22: 低压出线柜
C23: 低压联络柜
C24: 低压ATS切换柜
C25: 低压MTS切换柜
C26: 低压电容补偿柜
C27: 低压油机配电柜
C28: 应急油机接入箱
C29: 应急油机接入柜
C30: 低压楼层配电柜
C31: 低压交流配电柜
... C48: UPS并机柜
B49: 交流母线配电 | C49: 交流母线配电
C50: 始端箱
C51: 插接箱
A52: 变压器 | B52: 变压器 | C52: 干式变压器
C53: 油浸变压器
C54: 非晶合金变压器
C55: 调压器
A56: 低压直流配电 | B56: 低压直流配电 | C56: 24V直流配电箱
C57: -48V直流配电柜
C58: -48V直流列头柜
C59: -48V直流配电箱
...

Sheet 1.站点动环属性
A1: 序号 | B1: 字段 | C1: 英文名称 | D1: 字段类型 | E1: 数据来源 | F1: 是否必填 | G1: 内容说明 | H1: 范例 | I1: 是否部省接口同步 | J1: 同步模型说明 | K1: 是否最小集 | L1: 是否支撑生产关键字段
A2: 1 | B2: 资源标识 | C2: res_code | D2: 字符型 | E2: 自动生成 | F2: 是 | G2: 资管系统各资源的唯一标识 | H2: 37150202025645 | I2: 周粒度/日粒度 | K2: 是 | L2: 是
A3: 2 | B3: 所属省份 | C3: province_id | D3: 关联型 | E3: 自动生成 | F3: 是 | G3: 所属省份信息，关联省份表主键 | H3: 辽宁省 | I3: 周粒度/日粒度 | J3: 上报填写所属【省份】行政区域编码；范例：340000，仅部省同步字段 | K3: 是 | L3: 否
A4: 3 | B4: 所属地市 | C4: city_id | D4: 关联型 | E4: 自动生成 | F4: 是 | G4: 所属地市信息，关联地市表主键 | H4: 沈阳市 | I4: 周粒度/日粒度 | J4: 上报填写所属【地市】行政区域编码；范例：340100，仅部省同步字段 | K4: 是 | L4: 否
A5: 4 | B5: 所属区县 | C5: county_id | D5: 关联型 | E5: 自动生成 | F5: 是 | G5: 所属区县信息，关联区县表主键 | H5: 皇姑区 | I5: 周粒度/日粒度 | J5: 上报填写所属【区县】行政区域编码，范例：340103，仅部省同步字段 | K5: 是 | L5: 否
A6: 5 | B6: 站点名称 | C6: zh_label | D6: 关联型 | E6: 手工录入 | F6: 是 | G6: (关联)填写综合资源系统站点名称。关联到【空间资源】-站点-资源标识 | H6: 3715020203234 | I6: 周粒度/日粒度 | K6: 是 | L6: 是
A7: 6 | B7: 动环专业站点级别 | C7: power_site_level | D7: 枚举型 | E7: 手工录入 | F7: 是 | G7: 枚举参考powerSiteLevel 枚举值：通信机楼、数据中心、传输节点、通信基站。 | H7: 传输节点 | I7: 周粒度/日粒度 | K7: 是 | L7: 是
A8: 7 | B8: 市电备份方式 | C8: mains_backup_method | D8: 枚举型 | E8: 手工录入 | F8: 是 | G8: 枚举参考mainsBackupMethod 枚举值：单路引入、1+1热备、1+1冷备、N+0主用、N+1热备、N+1冷备、1+1主备、N+1主备 | H8: 单路引入 | I8: 周粒度/日粒度 | K8: 是 | L8: 是
A9: 8 | B9: 市电是否来自不同变电站 | C9: power_is_substations | D9: 枚举型 | E9: 手工录入 | F9: 是 | G9: 枚举参考powerIsSubstations 枚举值：是、否 | H9: 否 | I9: 周粒度/日粒度 | K9: 是 | L9: 是
A10: 9 | B10: 市电电压等级 | C10: mains_voltage_level | D10: 枚举型 | E10: 手工录入 | F10: 是 | G10: 枚举参考mainsVoltageLevel 枚举值：10KV以上、10KV、380V、220V、无市电 | H10: 380V | I10: 周粒度/日粒度 | K10: 是 | L10: 是
A11: 10 | B11: 市电性质 | C11: mains_nature | D11: 枚举型 | E11: 手工录入 | F11: 是 | G11: 枚举参考mainsNature 枚举值：市电转供、市电直供、风力发电、太阳能发电、风光互补，用于电费分析 | H11: 市电转供 | I11: 周粒度/日粒度 | K11: 是 | L11: 是
A12: 11 | B12: 动环监控站点名称 | C12: power_monitoring_site_name | D12: 字符型 | E12: 手工录入/自动采集 | F12: 存在必填 | G12: 填写动环监控系统中的站点名称 | H12: 沈阳皇姑昆山东路营业厅 | I12: 周粒度/日粒度 | K12: 是 | L12: 否
A13: 12 | B13: 市电总路数（路） | C13: total_mains_number | D13: 整数型 | E13: 手工录入 | F13: 存在必填 | G13: 没有市电引入的位置点可不填写，数据中心和通信机楼必填 | H13: 2 | I13: 周粒度/日粒度 | K13: 是 | L13: 是
A14: 13 | B14: 市电容量（KVA） | C14: mains_capacity | D14: 整数型 | E14: 手工录入 | F14: 存在必填 | G14: 没有市电引入的位置点可不填写，数据中心和通信机楼必填，各路市电容量用英文逗号“，”隔开 | H14: 10 | I14: 周粒度/日粒度 | K14: 是 | L14: 是
A15: 14 | B15: 市电油机配置级别 | C15: mains_configuration_level | D15: 枚举型 | E15: 手工录入 | F15: 存在必填 | G15: 数据中心和通信机楼必填。枚举值：1市电无油机、1市电1油机、2市电1油机、1市电2油机、2市电2油机 | H15: 1市电无油机 | I15: 周粒度/日粒度 | K15: 是 | L15: 是
A16: 15 | B16: 地下油罐总数量（个） | C16: total_tank_number | D16: 整数型 | E16: 手工录入 | F16: 存在必填 | G16: 单位：个，存在必填 | H16: 10 | I16: 周粒度/日粒度 | K16: 是 | L16: 否
A17: 16 | B17: 地下油罐总容积（m³） | C17: tatal_tank_volume | D17: 整数型 | E17: 手工录入 | F17: 存在必填 | G17: 单位：m³，存在必填 | H17: 500 | I17: 周粒度/日粒度 | K17: 是 | L17: 否
A18: 17 | B18: 产权单位 | C18: property_unit | D18: 枚举型 | E18: 自动生成 | F18: 否 | G18: 枚举参考propertyUnit 枚举：中国移动、中国联通、中国电信、中国铁塔，关联空间资源 | H18: 中国移动 | I18: 否 | K18: 是 | L18: 否
A19: 18 | B19: 市电引入情况 | C19: power_supply | D19: 枚举型 | E19: 手工录入 | F19: 存在必填 | G19: 枚举参考powerSupply 枚举值： 1.双变电站引入; 2.单变电站双母线引入； 3.园区自建变电站； 4.其他（请说明） | H19: 双变电站引入 | I19: 周粒度/日粒度 | K19: 是 | L19: 是
A20: 19 | B20: 是否下挂IDC机房 | C20: is_attach_idc_room | D20: 枚举型 | E20: 自动生成 | F20: 是 | G20: 根据【空间资源】中【站点】下是否含有IDC机房自动判断生成 枚举参考isAttachIdcRoom 枚举值： 1.是 2.否 | H20: 是 | I20: 周粒度/日粒度 | K20: 是 | L20: 是
A21: 20 | B21: 设计PUE | C21: design_pue | D21: 字符型 | E21: 手工录入 | F21: 存在必填 | G21: 规划设计的PUE（当“是否下挂IDC机房”为“是”时填写） | H21: 1.1 | I21: 周粒度/日粒度 | K21: 是 | L21: 是
A22: 21 | B22: 实际PUE | C22: actual_pue | D22: 字符型 | E22: 手工录入 | F22: 存在必填 | G22: 填写上一年PUE平均值（当“是否下挂IDC机房”为“是”时填写） | H22: 1.1 | I22: 周粒度/日粒度 | K22: 是 | L22: 是
A23: 22 | B23: 水冷机组配置情况 | C23: water_cooling_conf | D23: 枚举型 | E23: 手工录入 | F23: 存在必填 | G23: 枚举参考waterCoolingConf 枚举值： 1.N+1 2.N 3.其他 4.无 （当“是否下挂IDC机房”为“是”时必填） | H23: N | I23: 周粒度/日粒度 | K23: 是 | L23: 是
A24: 23 | B24: 是否安装蓄冷罐 | C24: is_cold_storage_install | D24: 枚举型 | E24: 手工录入 | F24: 存在必填 | G24: 枚举参考isColdStorageInstall 枚举值：1、是；2、否（当“是否下挂IDC机房”为“是”时必填） | H24: 是 | I24: 周粒度/日粒度 | K24: 是 | L24: 是
A25: 24 | B25: 蓄冷时长 | C25: cold_storage_time | D25: 字符型 | E25: 手工录入 | F25: 存在必填 | G25: 单位：分钟（当“是否下挂IDC机房”为“是”时必填，，"是否安装蓄冷罐"为"否"时可填0）） | H25: 15 | I25: 周粒度/日粒度 | K25: 是 | L25: 是
A26: 25 | B26: 动环监控站点ID | C26: power_monitoring_site_id | D26: 字符型 | E26: 手工录入/自动采集 | F26: 存在必填 | G26: 填写动环监控系统中的站点ID | H26: 5315020201 | I26: 周粒度/日粒度 | K26: 否 | L26: 否

Sheet 2.机房动环属性
A1: 序号 | B1: 字段 | C1: 英文名称 | D1: 字段类型 | E1: 数据来源 | F1: 是否必填 | G1: 内容说明 | H1: 范例 | I1: 是否部省接口同步 | J1: 同步模型说明 | K1: 是否最小集 | L1: 是否支撑生产关键字段
A2: 1 | B2: 资源标识 | C2: res_code | D2: 字符型 | E2: 自动生成 | F2: 是 | G2: 资管系统各资源的唯一标识 | H2: 37150202025645 | I2: 周粒度/日粒度 | K2: 是 | L2: 是
A3: 2 | B3: 所属省份 | C3: province_id | D3: 关联型 | E3: 自动生成 | F3: 是 | G3: 所属省份信息，关联省份表主键 | H3: 辽宁省 | I3: 周粒度/日粒度 | J3: 上报填写所属【省份】行政区域编码；范例：340000，仅部省同步字段 | K3: 是 | L3: 否
A4: 3 | B4: 所属地市 | C4: city_id | D4: 关联型 | E4: 自动生成 | F4: 是 | G4: 所属地市信息，关联地市表主键 | H4: 铁岭市 | I4: 周粒度/日粒度 | J4: 上报填写所属【地市】行政区域编码；范例：340100，仅部省同步字段 | K4: 是 | L4: 否
A5: 4 | B5: 所属区县 | C5: county_id | D5: 关联型 | E5: 自动生成 | F5: 是 | G5: 所属区县信息，关联区县表主键 | H5: 银州区 | I5: 周粒度/日粒度 | J5: 上报填写所属【区县】行政区域编码，范例：340103，仅部省同步字段 | K5: 是 | L5: 否
A6: 5 | B6: 机房名称 | C6: zh_label | D6: 关联型 | E6: 手工录入 | F6: 是 | G6: （关联）关联到【空间资源】-【机房】表 或 【资源点】表的资源标识 | H6: 铁岭柴河街局1号楼4层410A综合机房 | I6: 周粒度/日粒度 | J6: 上报填写所属【空间资源】-【机房】的资源标识；范例：3715020203234 | K6: 是 | L6: 是
A7: 6 | B7: 动环专业机房类型 | C7: power_room_type | D7: 枚举型 | E7: 手工录入 | F7: 是 | G7: 枚举参考powerRoomType | H7: 核心机房、汇聚机房 | I7: 周粒度/日粒度 | K7: 是 | L7: 是
A8: 7 | B8: 动环监控机房名称 | C8: power_room_name | D8: 字符型 | E8: 手工录入/自动采集 | F8: 存在必填 | G8: 填写动环监控系统中的机房名称 | H8: 铁岭柴河街局1号楼4层410A综合机房 | I8: 周粒度/日粒度 | K8: 是 | L8: 否
A9: 8 | B9: 所属站点 | C9: power_related_site_name | D9: 关联型 | E9: 自动生成 | F9: 是 | G9: (关联)关联到【空间资源】-站点或资源点 | H9: 铁岭柴河街局1号楼 | I9: 周粒度/日粒度 | J9: 上报填写所属【空间资源】-【站点】的资源标识；范例：3715020203234 | K9: 是 | L9: 是
A10: 9 | B10: 空间专业机房类型 | C10: space_room_type | D10: 关联型 | E10: 自动生成 | F10: 是 | G10: 关联到【空间资源】-【机房】表-【机房类型】 枚举参考spaceRoomType 枚举值： 1:核心机房 2:无线机房 3:数据机房 4:传输机房 5:动力机房 6:IDC机房 7:用户机房 8:其他机房 | H10: IDC机房 | I10: 周粒度/日粒度 | K10: 是 | L10: 是
A11: 10 | B11: 电池后备时间 | C11: battery_backup_time | D11: 浮点型 | E11: 手工录入 | F11: 存在必填 | G11: 电池后备时间，单位：分钟（当“空间专业机房类型”为“IDC机房”或者有OLT设备的机房必填） | H11: 15.0 | I11: 周粒度/日粒度 | K11: 是 | L11: 是
A12: 11 | B12: 供电模式 | C12: power_supply_mode | D12: 枚举型 | E12: 手工录入 | F12: 存在必填 | G12: 枚举参考powerSupplyMode 枚举值： 1：双电源双回路供电 2：单电源双回路供电 3、其他 （当“空间专业机房类型”为“IDC机房”时必填） | H12: 双电源双回路供电 | I12: 周粒度/日粒度 | K12: 是 | L12: 是
A13: 12 | B13: 电源类型 | C13: power_supply_type | D13: 枚举型 | E13: 手工录入 | F13: 存在必填 | G13: 枚举参考powerSupplyType 枚举值： 1.交流220V 2.交流380V 3.直流240V 4.直流336V 5.直流48V 6.直流110V 省内可根据实际情况扩展，且可多选，英文逗号分隔。 （当“空间专业机房类型”为“IDC机房”时必填） | H13: 220V交流 | I13: 周粒度/日粒度 | K13: 是 | L13: 是
A14: 13 | B14: 空调末端 | C14: ac_terminal | D14: 枚举型 | E14: 手工录入 | F14: 存在必填 | G14: 枚举参考acTerminal 枚举值： 1.精密空调 2.行间空调 3.新型末端（水冷前门） 4.新型末端（热管背板） 5.其他，如液冷、间接蒸发冷却等 可多选，英文逗号分隔。 （当“空间专业机房类型”为“IDC机房”时必填） | H14: 新型末端（水冷前门） | I14: 周粒度/日粒度 | K14: 是 | L14: 是
A15: 14 | B15: 空调配置情况 | C15: ac_config | D15: 枚举型 | E15: 手工录入 | F15: 存在必填 | G15: 枚举参考acConfig 枚举值： 1、N+X(冗余20%以上) 2、N+1冗余 3、N冗余 4、其他 （当“空间专业机房类型”为“IDC机房”时必填） | H15: N+X(冗余20%以上) | I15: 周粒度/日粒度 | K15: 是 | L15: 是
A16: 15 | B16: 制冷方式 | C16: refrigeration_mode | D16: 枚举型 | E16: 手工录入 | F16: 存在必填 | G16: 枚举参考refrigerationMode 枚举值： 1、水冷N+1 2、水冷N 3、风冷 4、风冷+水冷（N+1） 5、风冷+水冷N （当“空间专业机房类型”为“IDC机房”时必填） | H16: 风冷+水冷（N+1） | I16: 周粒度/日粒度 | K16: 是 | L16: 是
A17: 16 | B17: 参考PUE值 | C17: refer_pue | D17: 字符型 | E17: 手工录入 | F17: 存在必填 | G17: 参照PUE值（当“空间专业机房类型”为“IDC机房”时必填） | H17: 1.1 | I17: 周粒度/日粒度 | K17: 是 | L17: 是
A18: 17 | B18: 动环监控配置情况 | C18: power_monitor_conf | D18: 字符型 | E18: 手工录入 | F18: 存在必填 | G18: 主要描述如下信息：有无监控，若有监控则描述有无动力环境监控、有无消防监控、是否可监控每个机架电流电量（当“空间专业机房类型”为“IDC机房”时必填） | H18: 有动力环境监控、消防监控，可以监控机架电流 | I18: 周粒度/日粒度 | K18: 是 | L18: 是
A19: 18 | B19: 视频监控配置情况 | C19: video_monitor_conf | D19: 字符型 | E19: 手工录入 | F19: 存在必填 | G19: 主要描述如下信息：房门有无正对的摄像机，机房模块内是否覆盖所有区域，是否满足监控无死角，是否满足7*24小时视频监控，视频资料保存时长(单位：月） （当“空间专业机房类型”为“IDC机房”时必填） | H19: 房门有正对的摄像机，机房模块内覆盖所有区域，监控无死角，7*24小时视频监控，视频资料保存时长12个月 | I19: 周粒度/日粒度 | K19: 是 | L19: 是
A20: 19 | B20: 日志保存时长 | C20: log_saved_time | D20: 整数型 | E20: 手工录入 | F20: 存在必填 | G20: 门禁、视频监控等记录日志保存时长（单位：月） （当“空间专业机房类型”为“IDC机房”时必填） | H20: 3 | I20: 周粒度/日粒度 | K20: 是 | L20: 是
A21: 20 | B21: 动环监控机房ID | C21: power_room_id | D21: 字符型 | E21: 手工录入/自动采集 | F21: 存在必填 | G21: 填写动环监控系统中的机房ID | H21: 85785766 | I21: 周粒度/日粒度 | K21: 否 | L21: 否
A22: 21 | B22: 动环监控所属站点名称 | D22: 枚举型 | E22: 自动生成 | F22: 存在必填 | G22: 自动生成。关联到【位置点动环属性】的【动环监控站点名称】，以资源系统为准 | I22: 否 | K22: 是 | L22: 否
A23: 22 | B23: 是否有摄像机 | D23: 枚举型 | E23: 手工录入 | F23: 存在必填 | G23: 枚举值：是，否 | H23: 是 | I23: 否 | K23: 是 | L23: 否
A24: 23 | B24: 是否有红外 | D24: 枚举型 | E24: 手工录入 | F24: 存在必填 | G24: 枚举值：是，否 | H24: 是 | I24: 否 | K24: 是 | L24: 否
A25: 24 | B25: 是否有门禁 | D25: 枚举型 | E25: 手工录入 | F25: 存在必填 | G25: 枚举值：是，否。只安装门磁也算 | H25: 是 | I25: 否 | K25: 是 | L25: 否
A26: 25 | B26: 是否有水浸 | D26: 枚举型 | E26: 手工录入 | F26: 存在必填 | G26: 枚举值：是，否 | H26: 是 | I26: 否 | K26: 是 | L26: 否
A27: 26 | B27: 是否有烟感 | D27: 枚举型 | E27: 手工录入 | F27: 存在必填 | G27: 枚举值：是，否 | H27: 是 | I27: 否 | K27: 是 | L27: 否
A28: 27 | B28: 是否有温湿度 | D28: 枚举型 | E28: 手工录入 | F28: 存在必填 | G28: 枚举值：是，否 | H28: 是 | I28: 否 | K28: 是 | L28: 否
A29: 28 | B29: 是否有玻碰 | D29: 枚举型 | E29: 手工录入 | F29: 存在必填 | G29: 枚举值：是，否 | H29: 否 | I29: 否 | K29: 是 | L29: 否

Sheet 3.变压器
A1: 序号 | B1: 字段 | C1: 英文名称 | D1: 字段类型 | E1: 数据来源 | F1: 是否必填 | G1: 内容说明 | H1: 范例 | I1: 是否部省接口同步 | J1: 同步模型说明 | K1: 是否最小集 | L1: 是否支撑生产关键字段
A2: 1 | B2: 资源标识 | C2: res_code | D2: 字符型 | E2: 自动生成 | F2: 是 | G2: 资管系统各资源的唯一标识 | H2: 37150202025645 | I2: 周粒度/日粒度 | K2: 是 | L2: 是
A3: 2 | B3: 所属省份 | C3: province_id | D3: 关联型 | E3: 自动生成 | F3: 是 | G3: 所属省份信息，关联省份表主键 | H3: 北京市 | I3: 周粒度/日粒度 | J3: 上报填写所属【省份】行政区域编码；范例：340000，仅部省同步字段 | K3: 否 | L3: 否
A4: 3 | B4: 所属地市 | C4: city_id | D4: 关联型 | E4: 自动生成 | F4: 是 | G4: 所属地市信息，关联地市表主键 | H4: 北京市 | I4: 周粒度/日粒度 | J4: 上报填写所属【地市】行政区域编码；范例：340100，仅部省同步字段 | K4: 否 | L4: 否
A5: 4 | B5: 所属区县 | C5: county_id | D5: 关联型 | E5: 自动生成 | F5: 是 | G5: 所属区县信息，关联区县表主键 | H5: 大兴区 | I5: 周粒度/日粒度 | J5: 上报填写所属【区县】行政区域编码，范例：340103，仅部省同步字段 | K5: 否 | L5: 否
A6: 5 | B6: 所属站点 | C6: related_site | D6: 关联型 | E6: 自动生成 | F6: 存在必填 | G6: 自动生成。根据机房所属站点自动生成。当所属机房为资源点时，所属站点可为空。所属机房为机房时必填 | H6: 北京大兴区大白楼工业区 | I6: 周粒度/日粒度 | J6: 上报填写所属【空间资源】-【站点】的资源标识；范例：3715020203234 | K6: 否 | L6: 是
A7: 6 | B7: 所属机房 | C7: related_room | D7: 关联型 | E7: 手工录入 | F7: 是 | G7: （关联）关联到空间资源中【机房】-资源标识。如为室外设备，可关联至空间资源【位置点（资源点）】-资源标识。 | H7: 北京大兴区大白楼工业区核心机房 | I7: 周粒度/日粒度 | J7: 上报填写所属【空间资源】-【机房】的资源标识；范例：3715020203234 | K7: 是 | L7: 是
A8: 7 | B8: 设备类型 | C8: device_type | D8: 枚举型 | E8: 自动生成 | F8: 是 | G8: 枚举参考【设备类型&子类】 | H8: 变压器 | I8: 周粒度/日粒度 | K8: 是 | L8: 是
A9: 8 | B9: 设备子类 | C9: device_subclass | D9: 枚举型 | E9: 手工录入 | F9: 是 | G9: 枚举参考【设备类型&子类】 | H9: 油浸变压器 | I9: 周粒度/日粒度 | K9: 是 | L9: 是
A10: 9 | B10: 设备顺序号 | C10: device_number | D10: 字符型 | E10: 自动生成 | F10: 否 | G10: 站点内相同子类的顺序编号.从1开始。 | H10: 1 | I10: 周粒度/日粒度 | K10: 是 | L10: 否
A11: 10 | B11: 设备名称 | C11: zh_label | D11: 字符型 | E11: 自动生成 | F11: 是 | G11: 根据集团最新命名规范自动生成 | H11: 北京大兴区大白楼工业区-变压器-1 | I11: 周粒度/日粒度 | K11: 是 | L11: 是
A12: 11 | B12: 设备编码 | C12: device_code | D12: 字符型 | E12: 自动生成 | F12: 是 | G12: 根据集团最新命名规范自动生成 | H12: 0301 | I12: 周粒度/日粒度 | K12: 是 | L12: 是
A13: 12 | B13: 设备型号 | C13: product_name | D13: 枚举型 | E13: 手工录入 | F13: 是 | G13: 参照枚举值在动环设备型号名称中选择。各省新增动环设备型号名称需报备总部后才能执行。 | H13: S11-630KA | I13: 周粒度/日粒度 | K13: 是 | L13: 是
A14: 13 | B14: 设备厂家 | C14: vendor_id | D14: 枚举型 | E14: 手工录入 | F14: 是 | G14: 参照枚举值在动环设备厂商名称中选择。各省新增动环设备厂家名称需报备总部后才能执行。 | H14: 北京昊诚 | I14: 周粒度/日粒度 | K14: 是 | L14: 是
A15: 14 | B15: 额定功率（KVA） | C15: rated_power | D15: 整数型 | E15: 手工录入 | F15: 是 | G15: 额定视在功率，单位：KVA | H15: 630 | I15: 周粒度/日粒度 | K15: 是 | L15: 是
A16: 15 | B16: 输入额定电压（V） | C16: input_rated_voltage | D16: 枚举型 | E16: 手工录入 | F16: 是 | G16: 枚举参考inputRatedVoltage 枚举值：10KV以上、10KV，其它各省公司可调增 | H16: 10KV | I16: 周粒度/日粒度 | K16: 是 | L16: 是
A17: 16 | B17: 低压额定电流 | C17: low_reted_current | D17: 字符型 | E17: 手工录入 | F17: 是 | G17: 从设备铭牌读取 | H17: 10 | I17: 周粒度/日粒度 | K17: 否 | L17: 是
A18: 17 | B18: 备份方式 | C18: backup_method | D18: 枚举型 | E18: 手工录入 | F18: 是 | G18: 枚举参考backupMethod 枚举值：单台设备、1+1热备、1+1冷备、N+0主用、N+1热备、N+1冷备，其它备份方式枚举值各省公司可调增。应将N改为具体数值，如2+1热备 | H18: 1+1热备 | I18: 周粒度/日粒度 | K18: 是 | L18: 是
A19: 18 | B19: 设备串号 | C19: serial_number | D19: 字符型 | E19: 手工录入/自动采集 | F19: 否 | G19: 与资产进行关联的字段，即设备串号，对于OMC北向规范能采集到的，建议采集；无北向规范或北向规范不支持的，不做要求。 | H19: tr11111 | I19: 否 | K19: 否 | L19: 是
A20: 19 | B20: 资产标签号 | C20: assets_no | D20: 字符型 | E20: 手工录入 | F20: 存在必填 | G20: 对应资产管理系统设备资产标签号 | H20: 2226-10011001 | I20: 周粒度/日粒度 | K20: 是 | L20: 是
A21: 20 | B21: 开始使用时间 | C21: start_time | D21: 日期型 | E21: 手工录入 | F21: 是 | G21: 格式为：YYYY-MM-DD | H21: 2017-03-10 | I21: 周粒度/日粒度 | K21: 是 | L21: 是
A22: 21 | B22: 预计报废时间 | C22: estimated_retirement_time | D22: 日期型 | E22: 自动生成 | F22: 是 | G22: 格式为：YYYY-MM-DD，参考动力设备维护规程设备更新周期 | H22: 2017-03-10 | I22: 周粒度/日粒度 | K22: 是 | L22: 否
A23: 22 | B23: 使用状态 | C23: lifecycle_status | D23: 枚举型 | E23: 手工录入 | F23: 是 | G23: 枚举参考lifecycle_status 枚举值：现网、工程、退网、空载 | H23: 现网 | I23: 周粒度/日粒度 | K23: 是 | L23: 是
A24: 23 | B24: 维护责任人 | C24: maintainor | D24: 字符型 | E24: 手工录入 | F24: 是 | G24: 姓名 | H24: 王鹏 | I24: 周粒度/日粒度 | K24: 是 | L24: 否
A25: 24 | B25: 数据质量责任人（移动） | C25: qualitor | D25: 字符型 | E25: 手工录入 | F25: 是 | G25: 系统数据录入人员 | H25: 王鹏 | I25: 周粒度/日粒度 | K25: 否 | L25: 否
A26: 25 | B26: 项目编码 | C26: project_code | D26: 字符型 | E26: 手工录入 | F26: 否 | G26: 该设备所属工程项目编号 | H26: C1825523 | I26: 否 | K26: 否 | L26: 否
A27: 26 | B27: 项目名称 | C27: project_name | D27: 字符型 | E27: 自动生成 | F27: 否 | G27: 该设备所属工程项目名称 | H27: 2018年XX市机房动力项目 | I27: 否 | K27: 否 | L27: 否
A28: 27 | B28: 任务名称 | C28: long_task_name | D28: 字符型 | E28: 手工录入 | F28: 否 | G28: 该设备所属工程任务名称 | H28: 北京大兴区大白楼工业区核心机房 | I28: 否 | K28: 否 | L28: 否
A29: 28 | B29: 二维码编码 | C29: qr_code_no | D29: 字符型 | E29: 系统生成 | F29: 存在必填 | G29: 按照二维码规范生成二维码编码，用于资源APP现场扫描设备标签。 | H29: 510102019098494 | I29: 周粒度/日粒度 | K29: 否 | L29: 否
A30: 29 | B30: 动环监控设备名称 | C30: power_device_name | D30: 字符型 | E30: 手工录入/自动采集 | F30: 存在必填 | G30: 填写动环监控系统中的设备名称 | H30: 杭州白马公寓1高压配电系统1变压器 | I30: 周粒度/日粒度 | K30: 否 | L30: 否
A31: 30 | B31: 动环监控设备ID | C31: power_device_id | D31: 字符型 | E31: 手工录入/自动采集 | F31: 存在必填 | G31: 填写动环监控系统中的设备ID | H31: 85785766 | I31: 周粒度/日粒度 | K31: 否 | L31: 否
A32: 31 | B32: 设备品牌 | D32: 关联型 | E32: 自动生成 | F32: 是 | G32: 设备品牌，只能在动环设备厂家名称梳理表中选择，可自行扩展需报备总部后才能执行 | H32: 金盘 | I32: 否 | K32: 是 | L32: 否
A33: 32 | B33: 所属机架位置 | D33: 关联型 | E33: 手工录入 | F33: 否 | G33: 关联到【空间资源】-【机架位置】-【机架位置编号】 | I33: 否 | K33: 是 | L33: 否

Sheet 4.变换设备
A1: 序号 | B1: 字段 | C1: 英文名称 | D1: 字段类型 | E1: 数据来源 | F1: 是否必填 | G1: 内容说明 | H1: 范例 | I1: 是否部省接口同步 | J1: 同步模型说明 | K1: 是否最小集 | L1: 是否支撑生产关键字段
A2: 1 | B2: 资源标识 | C2: res_code | D2: 字符型 | E2: 自动生成 | F2: 是 | G2: 资管系统各资源的唯一标识 | H2: 37150202025645 | I2: 周粒度 | K2: 是 | L2: 是
A3: 2 | B3: 所属省份 | C3: province_id | D3: 关联型 | E3: 自动生成 | F3: 是 | G3: 所属省份信息，关联省份表主键 | H3: 浙江省 | I3: 周粒度 | J3: 上报填写所属【省份】行政区域编码；范例：340000，仅部省同步字段 | K3: 否 | L3: 否
A4: 3 | B4: 所属地市 | C4: city_id | D4: 关联型 | E4: 自动生成 | F4: 是 | G4: 所属地市信息，关联地市表主键 | H4: 杭州市 | I4: 周粒度 | J4: 上报填写所属【地市】行政区域编码；范例：340100，仅部省同步字段 | K4: 否 | L4: 否
A5: 4 | B5: 所属区县 | C5: county_id | D5: 关联型 | E5: 自动生成 | F5: 是 | G5: 所属区县信息，关联区县表主键 | H5: 西湖区 | I5: 周粒度 | J5: 上报填写所属【区县】行政区域编码，范例：340103，仅部省同步字段 | K5: 否 | L5: 否
A6: 5 | B6: 所属站点 | C6: related_site | D6: 关联型 | E6: 自动生成 | F6: 存在必填 | G6: 自动生成。根据机房所属站点自动生成。当所属机房为资源点时，所属站点可为空。所属机房为机房时必填 | H6: 杭州白马公寓 | I6: 周粒度 | J6: 上报填写所属【空间资源】-【站点】的资源标识；范例：3715020203234 | K6: 否 | L6: 是
A7: 6 | B7: 所属机房 | C7: related_room | D7: 关联型 | E7: 手工录入 | F7: 是 | G7: （关联）关联到空间资源中【机房】-资源标识。如为室外设备，可关联至空间资源【位置点（资源点）】-资源标识。 | H7: 杭州白马公寓3楼机房 | I7: 周粒度 | J7: 上报填写所属【空间资源】-【机房】的资源标识；范例：3715020203234 | K7: 是 | L7: 是
A8: 7 | B8: 设备类型 | C8: device_type | D8: 枚举型 | E8: 自动生成 | F8: 是 | G8: 枚举参考【设备类型&子类】 | H8: 变换设备 | I8: 周粒度 | K8: 是 | L8: 是
A9: 8 | B9: 设备子类 | C9: device_subclass | D9: 枚举型 | E9: 手工录入 | F9: 是 | G9: 枚举参考【设备类型&子类】 | H9: 交流逆变器 | I9: 周粒度 | K9: 是 | L9: 是
A10: 9 | B10: 设备顺序号 | C10: device_number | D10: 字符型 | E10: 自动生成 | F10: 否 | G10: 站点内相同子类的顺序编号 | H10: 1 | I10: 周粒度 | K10: 是 | L10: 否
A11: 10 | B11: 设备名称 | C11: zh_label | D11: 字符型 | E11: 自动生成 | F11: 是 | G11: 根据集团最新命名规范自动生成 | H11: 杭州白马公寓-变换设备-1-交流逆变器-1 | I11: 周粒度 | K11: 是 | L11: 是
A12: 11 | B12: 设备编码 | C12: device_code | D12: 字符型 | E12: 自动生成 | F12: 是 | G12: 根据集团最新命名规范自动生成 | H12: 1001 | I12: 周粒度 | K12: 是 | L12: 否
A13: 12 | B13: 设备型号 | C13: product_name | D13: 枚举型 | E13: 手工录入 | F13: 是 | G13: 参照枚举值在动环设备型号名称中选择。各省新增动环设备型号名称需报备总部后才能执行。 | H13: P6000-24-220 | I13: 周粒度 | K13: 是 | L13: 是
A14: 13 | B14: 设备厂家 | C14: vendor_id | D14: 枚举型 | E14: 手工录入 | F14: 是 | G14: 参照枚举值在动环设备厂商名称中选择。各省新增动环设备厂家名称需报备总部后才能执行。 | H14: 苏州迈力电器有限公司 | I14: 周粒度 | K14: 是 | L14: 是
A15: 14 | B15: 额定输入电压（V） | C15: rated_input_voltage | D15: 枚举型 | E15: 手工录入 | F15: 是 | G15: 枚举参考ratedInputVoltage 枚举值：24V、-48V，其他枚举值各省可自行增加 | H15: 24 | I15: 周粒度 | K15: 是 | L15: 是
A16: 15 | B16: 额定输出电压（V） | C16: rated_output_voltage | D16: 枚举型 | E16: 手工录入 | F16: 是 | G16: 枚举参考ratedOutputVoltage 枚举值：24V、-48V、220V、380V，其它电压枚举值各省可自行添加 | H16: 220 | I16: 周粒度 | K16: 是 | L16: 是
A17: 16 | B17: 输出类型 | C17: output_type | D17: 枚举型 | E17: 手工录入 | F17: 是 | G17: 枚举参考outputType 枚举值：交流、直流 | H17: 交流 | I17: 周粒度 | K17: 是 | L17: 是
A18: 17 | B18: 可装变换模块总数（块） | C18: total_loading_modules_number | D18: 整数型 | E18: 手工录入 | F18: 是 | G18: 单位：块 | H18: 3 | I18: 周粒度 | K18: 是 | L18: 是
A19: 18 | B19: 实配变换模块总数（块） | C19: total_match_modules_number | D19: 整数型 | E19: 手工录入 | F19: 是 | G19: 单位：块，最好与动环监控系统提取数据匹配 | H19: 2 | I19: 周粒度 | K19: 是 | L19: 是
A20: 19 | B20: 单个模块额定输出电流（A) | C20: single_module_output_current | D20: 整数型 | E20: 手工录入 | F20: 是 | G20: 单个模块额定输出电流，单位：A | H20: 30 | I20: 周粒度 | K20: 是 | L20: 是
A21: 20 | B21: 单个模块额定容量（KVA） | C21: signal_rated_capacity | D21: 整数型 | E21: 手工录入 | F21: 否 | G21: 单模块额定视在功率，单位：KVA。逆变器必填 | H21: 6.6 | I21: 否 | K21: 是 | L21: 是
A22: 21 | B22: 设备串号 | C22: serial_number | D22: 字符型 | E22: 手工录入/自动采集 | F22: 否 | G22: 与资产进行关联的字段，即设备串号，对于OMC北向规范能采集到的，建议采集；无北向规范或北向规范不支持的，不做要求。 | H22: tr10111 | I22: 否 | K22: 否 | L22: 是
A23: 22 | B23: 资产标签号 | C23: assets_no | D23: 字符型 | E23: 手工录入 | F23: 存在必填 | G23: 对应资产管理系统设备资产标签号 | H23: 2226-66666666 | I23: 周粒度 | K23: 是 | L23: 是
A24: 23 | B24: 开始使用时间 | C24: start_time | D24: 日期型 | E24: 手工录入 | F24: 是 | G24: 格式为：YYYY-MM-DD | H24: 2020-07-24 | I24: 周粒度 | K24: 是 | L24: 是
A25: 24 | B25: 预计报废时间 | C25: estimated_retirement_time | D25: 日期型 | E25: 自动生成 | F25: 是 | G25: 格式为：YYYY-MM-DD，参考动力设备维护规程设备更新周期 | H25: 2030-07-24 | I25: 周粒度 | K25: 是 | L25: 否
A26: 25 | B26: 使用状态 | C26: lifecycle_status | D26: 枚举型 | E26: 手工录入 | F26: 是 | G26: 枚举参考lifecycle_status 枚举值：现网、工程、退网、空载 | H26: 现网 | I26: 周粒度 | K26: 是 | L26: 是
A27: 26 | B27: 维护责任人 | C27: maintainor | D27: 字符型 | E27: 手工录入 | F27: 是 | G27: 维护责任人 | H27: 王工 | I27: 周粒度 | K27: 是 | L27: 否
A28: 27 | B28: 数据质量责任人（移动） | C28: qualitor | D28: 字符型 | E28: 手工录入 | F28: 是 | G28: 系统数据录入人员 | H28: 李工 | I28: 周粒度 | K28: 否 | L28: 否
A29: 28 | B29: 项目编码 | C29: project_code | D29: 字符型 | E29: 手工录入 | F29: 否 | G29: 该设备所属工程项目编号 | H29: C1825523 | I29: 否 | K29: 否 | L29: 否
A30: 29 | B30: 项目名称 | C30: project_name | D30: 字符型 | E30: 自动生成 | F30: 否 | G30: 该设备所属工程项目名称 | H30: 2018年XX市机房动力项目 | I30: 否 | K30: 否 | L30: 否
A31: 30 | B31: 任务名称 | C31: long_task_name | D31: 字符型 | E31: 手工录入 | F31: 否 | G31: 该设备所属工程任务名称 | H31: 杭州白马公寓3楼机房 | I31: 否 | K31: 否 | L31: 否
A32: 31 | B32: 二维码编码 | C32: qr_code_no | D32: 字符型 | E32: 系统生成 | F32: 存在必填 | G32: 按照二维码规范生成二维码编码，用于资源APP现场扫描设备标签。 | H32: 510102019098494 | I32: 周粒度 | K32: 否 | L32: 否
A33: 32 | B33: 动环监控设备名称 | C33: power_device_name | D33: 字符型 | E33: 手工录入/自动采集 | F33: 存在必填 | G33: 填写动环监控系统中的设备名称 | H33: 杭州白马公寓-变换设备-1-交流逆变器-1 | I33: 周粒度 | K33: 否 | L33: 否
A34: 33 | B34: 动环监控设备ID | C34: power_device_id | D34: 字符型 | E34: 手工录入/自动采集 | F34: 存在必填 | G34: 填写动环监控系统中的设备ID | H34: 85785766 | I34: 周粒度 | K34: 否 | L34: 否
A35: 34 | B35: 设备品牌 | D35: 关联型 | E35: 自动生成 | F35: 是 | G35: 设备品牌，只能在动环设备厂家名称梳理表中选择，可自行扩展需报备总部后才能执行 | H35: 金盘 | I35: 否 | K35: 是 | L35: 否
A36: 35 | B36: 所属机架位置 | D36: 关联型 | E36: 手工录入 | F36: 否 | G36: 关联到【空间资源】-【机架位置】-【机架位置编号】 | I36: 否 | K36: 是 | L36: 否

Sheet 5.高压配电系统
A1: 序号 | B1: 字段 | C1: 英文名称 | D1: 字段类型 | E1: 数据来源 | F1: 是否必填 | G1: 内容说明 | H1: 范例 | I1: 是否部省接口同步 | J1: 同步模型说明 | K1: 是否最小集 | L1: 是否支撑生产关键字段
A2: 1 | B2: 资源标识 | C2: res_code | D2: 字符型 | E2: 自动生成 | F2: 是 | G2: 资管系统各资源的唯一标识 | H2: 37150202025645 | I2: 周粒度 | K2: 是 | L2: 是
A3: 2 | B3: 所属省份 | C3: province_id | D3: 关联型 | E3: 自动生成 | F3: 是 | G3: 所属省份信息，关联省份表主键 | H3: 北京市 | I3: 周粒度 | J3: 上报填写所属【省份】行政区域编码；范例：340000，仅部省同步字段 | K3: 否 | L3: 否
A4: 3 | B4: 所属地市 | C4: city_id | D4: 关联型 | E4: 自动生成 | F4: 是 | G4: 所属地市信息，关联地市表主键 | H4: 北京市 | I4: 周粒度 | J4: 上报填写所属【地市】行政区域编码；范例：340100，仅部省同步字段 | K4: 否 | L4: 否
A5: 4 | B5: 所属区县 | C5: county_id | D5: 关联型 | E5: 自动生成 | F5: 是 | G5: 所属区县信息，关联区县表主键 | H5: 大兴区 | I5: 周粒度 | J5: 上报填写所属【区县】行政区域编码，范例：340103，仅部省同步字段 | K5: 否 | L5: 否
A6: 5 | B6: 所属站点 | C6: related_site | D6: 关联型 | E6: 自动生成 | F6: 存在必填 | G6: 自动生成。根据机房所属站点自动生成。当所属机房为资源点时，所属站点可为空。所属机房为机房时必填 | H6: 北京大兴区大白楼工业区 | I6: 周粒度 | J6: 上报填写所属【空间资源】-【站点】的资源标识；范例：3715020203234 | K6: 否 | L6: 是
A7: 6 | B7: 所属机房 | C7: related_room | D7: 关联型 | E7: 手工录入 | F7: 是 | G7: （关联）关联到空间资源中【机房】-资源标识。如为室外设备，可关联至空间资源【位置点（资源点）】-资源标识。 | H7: 北京大兴区大白楼工业区核心机房 | I7: 周粒度 | J7: 上报填写所属【空间资源】-【机房】的资源标识；范例：3715020203234 | K7: 是 | L7: 是
A8: 7 | B8: 系统类型 | C8: system_type | D8: 枚举型 | E8: 自动生成 | F8: 是 | G8: 枚举参考systemType，填系统类型 | H8: 高压配电系统 | I8: 周粒度 | K8: 是 | L8: 是
A9: 8 | B9: 系统顺序号 | C9: system_number | D9: 字符型 | E9: 手工录入 | F9: 否 | G9: 站点内相同子类的顺序编号 | H9: 1 | I9: 周粒度 | K9: 是 | L9: 否
A10: 9 | B10: 系统名称 | C10: zh_label | D10: 字符型 | E10: 手工录入 | F10: 是 | G10: 根据集团最新命名规范填写 | H10: 北京大兴区大白楼工业区核心机房-高压配电系统-1 | I10: 周粒度 | K10: 是 | L10: 是
A11: 10 | B11: 系统编码 | C11: system_code | D11: 字符型 | E11: 自动生成 | F11: 是 | G11: 根据集团最新命名规范自动生成 | H11: 51 | I11: 周粒度 | K11: 是 | L11: 否
A12: 11 | B12: 系统额定容量(KVA) | C12: system_rated_capacity | D12: 整数型 | E12: 手工录入 | F12: 是 | G12: 高压配电系统额定容量，单位：KVA | H12: 1600 | I12: 周粒度 | K12: 否 | L12: 是
A13: 12 | B13: 运行方式 | C13: operation_mode | D13: 枚举型 | E13: 手工录入 | F13: 否 | G13: 枚举参考operationMode 高压配电系统运行方式 | H13: 热备 | I13: 否 | K13: 是 | L13: 否
A14: 13 | B14: 使用状态 | C14: lifecycle_status | D14: 枚举型 | E14: 手工录入 | F14: 是 | G14: 枚举参考lifecycle_status 枚举值：现网、工程、退网、空载 | H14: 现网 | I14: 周粒度 | K14: 否 | L14: 是
A15: 14 | B15: 数据质量责任人（移动） | C15: qualitor | D15: 字符型 | E15: 手工录入 | F15: 是 | G15: 系统数据录入人员 | H15: 王鹏 | I15: 周粒度 | K15: 否 | L15: 否
A16: 15 | B16: 系统内配电柜名称 | D16: 关联型 | E16: 自动生成 | F16: 否 | G16: 系统自动汇总生成，系统内的配电柜设备名称；若有多个配电柜则用英文“;”分开。关联到【高压交流配电】的【设备名称】 | I16: 否 | K16: 是 | L16: 否

Sheet 6.高压配电
A1: 序号 | B1: 字段 | C1: 英文名称 | D1: 字段类型 | E1: 数据来源 | F1: 是否必填 | G1: 内容说明 | H1: 范例 | I1: 是否部省接口同步 | J1: 同步模型说明 | K1: 是否最小集 | L1: 是否支撑生产关键字段
A2: 1 | B2: 资源标识 | C2: res_code | D2: 字符型 | E2: 自动生成 | F2: 是 | G2: 资管系统各资源的唯一标识 | H2: 37150202025645 | I2: 周粒度 | K2: 是 | L2: 是
A3: 2 | B3: 所属省份 | C3: province_id | D3: 关联型 | E3: 自动生成 | F3: 是 | G3: 所属省份信息，关联省份表主键 | H3: 北京市 | I3: 周粒度 | J3: 上报填写所属【省份】行政区域编码；范例：340000，仅部省同步字段 | K3: 否 | L3: 否
A4: 3 | B4: 所属地市 | C4: city_id | D4: 关联型 | E4: 自动生成 | F4: 是 | G4: 所属地市信息，关联地市表主键 | H4: 北京市 | I4: 周粒度 | J4: 上报填写所属【地市】行政区域编码；范例：340100，仅部省同步字段 | K4: 否 | L4: 否
A5: 4 | B5: 所属区县 | C5: county_id | D5: 关联型 | E5: 自动生成 | F5: 是 | G5: 所属区县信息，关联区县表主键 | H5: 大兴区 | I5: 周粒度 | J5: 上报填写所属【区县】行政区域编码，范例：340103，仅部省同步字段 | K5: 否 | L5: 否
A6: 5 | B6: 所属站点 | C6: related_site | D6: 关联型 | E6: 自动生成 | F6: 存在必填 | G6: 自动生成。根据机房所属站点自动生成。当所属机房为资源点时，所属站点可为空。所属机房为机房时必填 | H6: 北京大兴区大白楼工业区 | I6: 周粒度 | J6: 上报填写所属【空间资源】-【站点】的资源标识；范例：3715020203234 | K6: 否 | L6: 是
A7: 6 | B7: 所属机房 | C7: related_room | D7: 关联型 | E7: 手工录入 | F7: 是 | G7: （关联）关联到空间资源中【机房】-资源标识。如为室外设备，可关联至空间资源【位置点（资源点）】-资源标识。 | H7: 北京大兴区大白楼工业区核心机房 | I7: 周粒度 | J7: 上报填写所属【空间资源】-【机房】的资源标识；范例：3715020203234 | K7: 是 | L7: 是
A8: 7 | B8: 设备类型 | C8: device_type | D8: 枚举型 | E8: 自动生成 | F8: 是 | G8: 枚举参考【设备类型&子类】 | H8: 高压配电 | I8: 周粒度 | K8: 是 | L8: 是
A9: 8 | B9: 设备子类 | C9: device_subclass | D9: 枚举型 | E9: 手工录入 | F9: 是 | G9: 枚举参考【设备类型&子类】 | H9: 高压出线柜 | I9: 周粒度 | K9: 是 | L9: 是
A10: 9 | B10: 设备顺序号 | C10: device_number | D10: 字符型 | E10: 自动生成 | F10: 否 | G10: 站点内相同子类的顺序编号 | H10: 1 | I10: 周粒度 | K10: 是 | L10: 否
A11: 10 | B11: 设备名称 | C11: zh_label | D11: 字符型 | E11: 自动生成 | F11: 是 | G11: 根据集团最新命名规范自动生成 | H11: 北京大兴区大白楼工业区核心机房-高压直流电源系统-1-高压出线柜-1 | I11: 周粒度 | K11: 是 | L11: 是
A12: 11 | B12: 设备编码 | C12: device_code | D12: 字符型 | E12: 自动生成 | F12: 是 | G12: 根据集团最新命名规范自动生成 | H12: 0110 | I12: 周粒度 | K12: 是 | L12: 否
A13: 12 | B13: 设备型号 | C13: product_name | D13: 枚举型 | E13: 手工录入 | F13: 是 | G13: 参照枚举值在动环设备型号名称中选择。各省新增动环设备型号名称需报备总部后才能执行。 | H13: UniGear ZS1 | I13: 周粒度 | K13: 是 | L13: 是
A14: 13 | B14: 设备厂家 | C14: vendor_id | D14: 枚举型 | E14: 手工录入 | F14: 是 | G14: 参照枚举值在动环设备厂商名称中选择。各省新增动环设备厂家名称需报备总部后才能执行。 | H14: 厦门ABB低压电器设备有限公司 | I14: 周粒度 | K14: 是 | L14: 是
A15: 14 | B15: 所属系统 | C15: related_system | D15: 关联型 | E15: 手动录入 | F15: 是 | G15: 关联到【高压配电系统】或者【发电系统】-资源标识。 | H15: 北京大兴区大白楼工业区核心机房-高压配电系统-1 | I15: 周粒度 | J15: 上报范例：37150202025645 | K15: 否 | L15: 是
A16: 15 | B16: 额定容量（A) | C16: reted_capacity | D16: 整数型 | E16: 手工录入 | F16: 是 | G16: 设备输出开关的容量，默认单位为A。电容补偿柜填写输入开关容量。数据中心和通信机楼必填 | H16: 630 | I16: 周粒度 | K16: 是 | L16: 是
A17: 16 | B17: 设备串号 | C17: serial_number | D17: 字符型 | E17: 手工录入/自动采集 | F17: 否 | G17: 与资产进行关联的字段，即设备串号，对于OMC北向规范能采集到的，建议采集；无北向规范或北向规范不支持的，不做要求。 | H17: sr77000713 | I17: 否 | K17: 否 | L17: 是
A18: 17 | B18: 资产标签号 | C18: assets_no | D18: 字符型 | E18: 手工录入 | F18: 存在必填 | G18: 对应资产管理系统设备资产标签号 | H18: 2226-18601860 | I18: 周粒度 | K18: 否 | L18: 是
A19: 18 | B19: 开始使用时间 | C19: start_time | D19: 日期型 | E19: 手工录入 | F19: 是 | G19: 格式为：YYYY-MM-DD | H19: 2020-07-24 | I19: 周粒度 | K19: 是 | L19: 是
A20: 19 | B20: 预计报废时间 | C20: estimated_retirement_time | D20: 日期型 | E20: 自动生成 | F20: 是 | G20: 格式为：YYYY-MM-DD，参考动力设备维护规程设备更新周期 | H20: 2035-07-24 | I20: 周粒度 | K20: 是 | L20: 否
A21: 20 | B21: 使用状态 | C21: lifecycle_status | D21: 枚举型 | E21: 手工录入 | F21: 是 | G21: 枚举参考lifecycle_status 枚举值：现网、工程、退网、空载 | H21: 现网 | I21: 周粒度 | K21: 是 | L21: 是
A22: 21 | B22: 维护责任人 | C22: maintainor | D22: 字符型 | E22: 手工录入 | F22: 是 | G22: 维护责任人 | H22: 王工 | I22: 周粒度 | K22: 是 | L22: 否
A23: 22 | B23: 数据质量责任人（移动） | C23: qualitor | D23: 字符型 | E23: 手工录入 | F23: 是 | G23: 系统数据录入人员 | H23: 李工 | I23: 周粒度 | K23: 否 | L23: 否
A24: 23 | B24: 项目编码 | C24: project_code | D24: 字符型 | E24: 手工录入 | F24: 否 | G24: 该设备所属工程项目编号 | H24: C1825523 | I24: 否 | K24: 否 | L24: 否
A25: 24 | B25: 项目名称 | C25: project_name | D25: 字符型 | E25: 自动生成 | F25: 否 | G25: 该设备所属工程项目名称 | H25: 2018年XX市机房动力项目 | I25: 否 | K25: 否 | L25: 否
A26: 25 | B26: 任务名称 | C26: long_task_name | D26: 字符型 | E26: 手工录入 | F26: 否 | G26: 该设备所属工程任务名称 | H26: 北京大兴区大白楼工业区核心机房 | I26: 否 | K26: 否 | L26: 否
A27: 26 | B27: 二维码编码 | C27: qr_code_no | D27: 字符型 | E27: 系统生成 | F27: 存在必填 | G27: 按照二维码规范生成二维码编码，用于资源APP现场扫描设备标签。 | H27: 510102019098494 | I27: 周粒度 | K27: 否 | L27: 否
A28: 27 | B28: 动环监控设备名称 | C28: power_device_name | D28: 字符型 | E28: 手工录入/自动采集 | F28: 存在必填 | G28: 填写动环监控系统中的设备名称 | H28: 北京大兴区大白楼工业区核心机房-高压直流电源系统-1-高压出线柜-1 | I28: 周粒度 | K28: 否 | L28: 否
A29: 28 | B29: 动环监控设备ID | C29: power_device_id | D29: 字符型 | E29: 手工录入/自动采集 | F29: 存在必填 | G29: 填写动环监控系统中的设备ID | H29: 85785766 | I29: 周粒度 | K29: 否 | L29: 否
A30: 29 | B30: 所属系统顺序号 | D30: 关联型 | E30: 手动录入 | F30: 存在必填 | G30: 关联到【高压配电系统】-【系统顺序号】，单选 | H30: 1 | I30: 否 | K30: 是 | L30: 否
A31: 30 | B31: 设备品牌 | D31: 关联型 | E31: 手工录入 | F31: 是 | G31: 设备品牌，只能在动环设备厂家名称梳理表中选择，可自行扩展需报备总部后才能执行 | H31: 施耐德 | I31: 否 | K31: 是 | L31: 否
A32: 31 | B32: 所属机架位置 | D32: 关联型 | E32: 手工录入 | F32: 否 | G32: 关联到【空间资源】-【机架位置】-【机架位置编号】 | I32: 否 | K32: 是 | L32: 否

Sheet 7.高压直流电源系统
A1: 序号 | B1: 字段 | C1: 英文名称 | D1: 字段类型 | E1: 数据来源 | F1: 是否必填 | G1: 内容说明 | H1: 范例 | I1: 是否部省接口同步 | J1: 同步模型说明 | K1: 是否最小集 | L1: 是否支撑生产关键字段
A2: 1 | B2: 资源标识 | C2: res_code | D2: 字符型 | E2: 自动生成 | F2: 是 | G2: 资管系统各资源的唯一标识 | H2: 37150202025645 | I2: 周粒度 | K2: 是 | L2: 是
A3: 2 | B3: 所属省份 | C3: province_id | D3: 关联型 | E3: 自动生成 | F3: 是 | G3: 所属省份信息，关联省份表主键 | H3: 北京市 | I3: 周粒度 | J3: 上报填写所属【省份】行政区域编码；范例：340000，仅部省同步字段 | K3: 否 | L3: 否
A4: 3 | B4: 所属地市 | C4: city_id | D4: 关联型 | E4: 自动生成 | F4: 是 | G4: 所属地市信息，关联地市表主键 | H4: 北京市 | I4: 周粒度 | J4: 上报填写所属【地市】行政区域编码；范例：340100，仅部省同步字段 | K4: 否 | L4: 否
A5: 4 | B5: 所属区县 | C5: county_id | D5: 关联型 | E5: 自动生成 | F5: 是 | G5: 所属区县信息，关联区县表主键 | H5: 大兴区 | I5: 周粒度 | J5: 上报填写所属【区县】行政区域编码，范例：340103，仅部省同步字段 | K5: 否 | L5: 否
A6: 5 | B6: 所属站点 | C6: related_site | D6: 关联型 | E6: 自动生成 | F6: 存在必填 | G6: 自动生成。根据机房所属站点自动生成。当所属机房为资源点时，所属站点可为空。所属机房为机房时必填 | H6: 北京大兴区大白楼工业区 | I6: 周粒度 | J6: 上报填写所属【空间资源】-【站点】的资源标识；范例：3715020203234 | K6: 否 | L6: 是
A7: 6 | B7: 所属机房 | C7: related_room | D7: 关联型 | E7: 手工录入 | F7: 是 | G7: （关联）关联到空间资源中【机房】-资源标识。如为室外设备，可关联至空间资源【位置点（资源点）】-资源标识。 | H7: 北京大兴区大白楼工业区核心机房 | I7: 周粒度 | J7: 上报填写所属【空间资源】-【机房】的资源标识；范例：3715020203234 | K7: 是 | L7: 是
A8: 7 | B8: 系统类型 | C8: system_type | D8: 枚举型 | E8: 自动生成 | F8: 是 | G8: 枚举参考systemType | H8: 高压直流电源系统 | I8: 周粒度 | K8: 是 | L8: 否
A9: 8 | B9: 系统顺序号 | C9: system_number | D9: 字符型 | E9: 手工录入 | F9: 否 | G9: 站点内相同子类的顺序编号 | H9: 1 | I9: 周粒度 | K9: 是 | L9: 否
A10: 9 | B10: 系统名称 | C10: zh_label | D10: 字符型 | E10: 手工录入 | F10: 是 | G10: 根据集团最新命名规范填写 | H10: 北京大兴区大白楼工业区核心机房-高压直流电源系统-1 | I10: 周粒度 | K10: 是 | L10: 是
A11: 10 | B11: 系统编码 | C11: system_code | D11: 字符型 | E11: 自动生成 | F11: 是 | G11: 根据集团最新命名规范自动生成 | H11: 55 | I11: 周粒度 | K11: 是 | L11: 否
A12: 11 | B12: 系统额定容量(A) | C12: system_rated_capacity | D12: 整数型/浮点型 | E12: 手工录入 | F12: 是 | G12: 高压直流系统额定容量，单位：A。系统实配总值 | H12: 400.5 | I12: 周粒度 | K12: 是 | L12: 是
A13: 12 | B13: 使用状态 | C13: lifecycle_status | D13: 枚举型 | E13: 手工录入 | F13: 是 | G13: 枚举参考lifecycle_status 枚举值：现网、工程、退网、空载 | H13: 现网 | I13: 周粒度 | K13: 否 | L13: 是
A14: 13 | B14: 数据质量责任人（移动） | C14: qualitor | D14: 字符型 | E14: 手工录入 | F14: 是 | G14: 系统数据录入人员 | H14: 李工 | I14: 周粒度 | K14: 否 | L14: 否
A15: 14 | B15: 是否5G关键网络设备 | D15: 枚举型 | E15: 手工录入 | F15: 是 | G15: 用于标注总部资管上为5G关键网络云资源池设备供电的电源系统及设备。 枚举值：是、否 | H15: 否 | I15: 否 | K15: 否 | L15: 否
A16: 15 | B16: 系统内设备名称 | D16: 关联型 | E16: 自动生成 | F16: 否 | G16: 系统自动赋值。高压直流系统内的直流配电柜名称；若有多个配电柜则用英文“;”分开。关联到【高压直流配电】的【设备名称】 | I16: 否 | K16: 是 | L16: 否

Sheet 8.高压直流电源
A1: 序号 | B1: 字段 | C1: 英文名称 | D1: 字段类型 | E1: 数据来源 | F1: 是否必填 | G1: 内容说明 | H1: 范例 | I1: 是否部省接口同步 | J1: 同步模型说明 | K1: 是否最小集 | L1: 是否支撑生产关键字段
A2: 1 | B2: 资源标识 | C2: res_code | D2: 字符型 | E2: 自动生成 | F2: 是 | G2: 资管系统各资源的唯一标识 | H2: 37150202025645 | I2: 周粒度 | K2: 是 | L2: 是
A3: 2 | B3: 所属省份 | C3: province_id | D3: 关联型 | E3: 自动生成 | F3: 是 | G3: 所属省份信息，关联省份表主键 | H3: 浙江省 | I3: 周粒度 | J3: 上报填写所属【省份】行政区域编码；范例：340000，仅部省同步字段 | K3: 否 | L3: 否
A4: 3 | B4: 所属地市 | C4: city_id | D4: 关联型 | E4: 自动生成 | F4: 是 | G4: 所属地市信息，关联地市表主键 | H4: 杭州市 | I4: 周粒度 | J4: 上报填写所属【地市】行政区域编码；范例：340100，仅部省同步字段 | K4: 否 | L4: 否
A5: 4 | B5: 所属区县 | C5: county_id | D5: 关联型 | E5: 自动生成 | F5: 是 | G5: 所属区县信息，关联区县表主键 | H5: 西湖区 | I5: 周粒度 | J5: 上报填写所属【区县】行政区域编码，范例：340103，仅部省同步字段 | K5: 否 | L5: 否
A6: 5 | B6: 所属站点 | C6: related_site | D6: 关联型 | E6: 自动生成 | F6: 存在必填 | G6: 自动生成。根据机房所属站点自动生成。当所属机房为资源点时，所属站点可为空。所属机房为机房时必填 | H6: 杭州白马公寓 | I6: 周粒度 | J6: 上报填写所属【空间资源】-【站点】的资源标识；范例：3715020203234 | K6: 否 | L6: 是
A7: 6 | B7: 所属机房 | C7: related_room | D7: 关联型 | E7: 手工录入 | F7: 是 | G7: （关联）关联到空间资源中【机房】-资源标识。如为室外设备，可关联至空间资源【位置点（资源点）】-资源标识。 | H7: 杭州白马公寓3楼机房 | I7: 周粒度 | J7: 上报填写所属【空间资源】-【机房】的资源标识；范例：3715020203234 | K7: 是 | L7: 是
A8: 7 | B8: 设备类型 | C8: device_type | D8: 枚举型 | E8: 自动生成 | F8: 是 | G8: 枚举参考【设备类型&子类】 | H8: 高压直流电源 | I8: 周粒度 | K8: 是 | L8: 否
A9: 8 | B9: 设备子类 | C9: device_subclass | D9: 枚举型 | E9: 手工录入 | F9: 是 | G9: 枚举参考【设备类型&子类】 | H9: 分立高压直流电源 | I9: 周粒度 | K9: 是 | L9: 是
A10: 9 | B10: 设备顺序号 | C10: device_number | D10: 字符型 | E10: 自动生成 | F10: 否 | G10: 站点内相同子类的顺序编号 | H10: 1 | I10: 周粒度 | K10: 是 | L10: 否
A11: 10 | B11: 设备名称 | C11: zh_label | D11: 字符型 | E11: 自动生成 | F11: 是 | G11: 根据集团最新命名规范自动生成 | H11: 杭州白马公寓-高压直流电源系统-1-分立高压直流电源-1 | I11: 周粒度 | K11: 是 | L11: 否
A12: 11 | B12: 设备编码 | C12: device_code | D12: 字符型 | E12: 自动生成 | F12: 是 | G12: 根据集团最新命名规范自动生成 | H12: 1202 | I12: 周粒度 | K12: 是 | L12: 否
A13: 12 | B13: 设备型号 | C13: product_name | D13: 枚举型 | E13: 手工录入 | F13: 是 | G13: 参照枚举值在动环设备型号名称中选择。各省新增动环设备型号名称需报备总部后才能执行。 | H13: HVP-336/37A(2000A及以下) | I13: 周粒度 | K13: 是 | L13: 是
A14: 13 | B14: 设备厂家 | C14: vendor_id | D14: 枚举型 | E14: 手工录入 | F14: 是 | G14: 参照枚举值在动环设备厂商名称中选择。各省新增动环设备厂家名称需报备总部后才能执行。 | H14: 中达电通股份有限公司 | I14: 周粒度 | K14: 是 | L14: 是
A15: 14 | B15: 所属系统 | C15: related_system | D15: 关联型 | E15: 手动录入 | F15: 是 | G15: （关联）关联到【高压直流电源系统】-资源标识，单选。 | H15: 杭州白马公寓-高压直流电源系统-1 | I15: 周粒度 | J15: 上报范例：5315020203 | K15: 否 | L15: 是
A16: 15 | B16: 额定输出电压（V） | C16: rated_output_voltage | D16: 枚举型 | E16: 手工录入 | F16: 是 | G16: 枚举参考ratedOutputVoltage 枚举值：360V，336V，240，可自行扩展 | H16: 336 | I16: 周粒度 | K16: 是 | L16: 是
A17: 16 | B17: 监控模块型号 | C17: monitoring_module_model | D17: 字符型 | E17: 手工录入 | F17: 是 | G17: 填写监控模块型号 | H17: HCU-18 | I17: 周粒度 | K17: 是 | L17: 是
A18: 17 | B18: 本机架可装整流模块总数（块） | C18: total_rack_loading_modules_number | D18: 整数型 | E18: 手工录入 | F18: 是 | G18: 单位：块 | H18: 10 | I18: 周粒度 | K18: 是 | L18: 是
A19: 18 | B19: 本机架实配整流模块总数（块） | C19: total_rack_match_modules_number | D19: 整数型 | E19: 手工录入 | F19: 是 | G19: 单位：块，与动环监控系统提取数据匹配 | H19: 6 | I19: 周粒度 | K19: 是 | L19: 是
A20: 19 | B20: 单个整流模块额定输出容量（A） | C20: signal_output_rated_capacity | D20: 整数型/浮点型 | E20: 手工录入 | F20: 是 | G20: 单个整流模块额定输出容量，单位：A | H20: 100.5 | I20: 周粒度 | K20: 是 | L20: 是
A21: 20 | B21: 设备串号 | C21: serial_number | D21: 字符型 | E21: 手工录入/自动采集 | F21: 否 | G21: 与资产进行关联的字段，即设备串号，对于OMC北向规范能采集到的，建议采集；无北向规范或北向规范不支持的，不做要求。 | H21: DR10001 | I21: 否 | K21: 否 | L21: 是
A22: 21 | B22: 资产标签号 | C22: assets_no | D22: 字符型 | E22: 手工录入 | F22: 存在必填 | G22: 对应资产管理系统设备资产标签号 | H22: 2226-18601860 | I22: 周粒度 | K22: 是 | L22: 是
A23: 22 | B23: 开始使用时间 | C23: start_time | D23: 日期型 | E23: 手工录入 | F23: 是 | G23: 格式为：YYYY-MM-DD | H23: 2020-07-24 | I23: 周粒度 | K23: 是 | L23: 是
A24: 23 | B24: 预计报废时间 | C24: estimated_retirement_time | D24: 日期型 | E24: 自动生成 | F24: 是 | G24: 格式为：YYYY-MM-DD，参考动力设备维护规程设备更新周期 | H24: 2030-07-24 | I24: 周粒度 | K24: 是 | L24: 否
A25: 24 | B25: 使用状态 | C25: lifecycle_status | D25: 枚举型 | E25: 手工录入 | F25: 是 | G25: 枚举参考lifecycle_status 枚举值：现网、工程、退网、空载 | H25: 现网 | I25: 周粒度 | K25: 是 | L25: 是
A26: 25 | B26: 维护责任人 | C26: maintainor | D26: 字符型 | E26: 手工录入 | F26: 是 | G26: 维护责任人 | H26: 王工 | I26: 周粒度 | K26: 是 | L26: 否
A27: 26 | B27: 数据质量责任人（移动） | C27: qualitor | D27: 字符型 | E27: 手工录入 | F27: 是 | G27: 系统数据录入人员 | H27: 李工 | I27: 周粒度 | K27: 否 | L27: 否
A28: 27 | B28: 项目编码 | C28: project_code | D28: 字符型 | E28: 手工录入 | F28: 否 | G28: 该设备所属工程项目编号 | H28: C1820012 | I28: 否 | K28: 否 | L28: 否
A29: 28 | B29: 项目名称 | C29: project_name | D29: 字符型 | E29: 自动生成 | F29: 否 | G29: 该设备所属工程项目名称 | H29: 2018年XX市机房动力项目 | I29: 否 | K29: 否 | L29: 否
A30: 29 | B30: 任务名称 | C30: long_task_name | D30: 字符型 | E30: 手工录入 | F30: 否 | G30: 该设备所属工程任务名称 | H30: 杭州白马公寓3楼机房 | I30: 否 | K30: 否 | L30: 否
A31: 30 | B31: 二维码编码 | C31: qr_code_no | D31: 字符型 | E31: 系统生成 | F31: 存在必填 | G31: 按照二维码规范生成二维码编码，用于资源APP现场扫描设备标签。 | H31: 510102019098494 | I31: 周粒度 | K31: 否 | L31: 否
A32: 31 | B32: 动环监控设备名称 | C32: power_device_name | D32: 字符型 | E32: 手工录入/自动采集 | F32: 存在必填 | G32: 填写动环监控系统中的设备名称 | H32: 杭州白马公寓-高压直流电源系统-1-分立高压直流电源-1 | I32: 周粒度 | K32: 否 | L32: 否
A33: 32 | B33: 动环监控设备ID | C33: power_device_id | D33: 字符型 | E33: 手工录入/自动采集 | F33: 存在必填 | G33: 填写动环监控系统中的设备ID | H33: 85785766 | I33: 周粒度 | K33: 否 | L33: 否
A34: 33 | B34: 是否5G关键网络设备 | D34: 枚举型 | E34: 手工录入 | F34: 是 | G34: 用于标注总部资管上为5G关键网络云资源池设备供电的电源系统及设备。 枚举值：是、否 | H34: 否 | I34: 否 | K34: 否 | L34: 否
A35: 34 | B35: 所属系统顺序号 | D35: 关联型 | E35: 手动录入 | F35: 存在必填 | G35: 关联到【高压配电系统】-【系统顺序号】，单选 | H35: 1 | I35: 否 | K35: 是 | L35: 否
A36: 35 | B36: 设备品牌 | D36: 关联型 | E36: 手工录入 | F36: 是 | G36: 设备品牌，只能在动环设备厂家名称梳理表中选择，可自行扩展需报备总部后才能执行 | H36: 施耐德 | I36: 否 | K36: 是 | L36: 否
A37: 36 | B37: 所属机架位置 | D37: 关联型 | E37: 手工录入 | F37: 否 | G37: 关联到【空间资源】-【机架位置】-【机架位置编号】 | I37: 否 | K37: 是 | L37: 否

Sheet 9.高压直流配电
A1: 序号 | B1: 字段 | C1: 英文名称 | D1: 字段类型 | E1: 数据来源 | F1: 是否必填 | G1: 内容说明 | H1: 范例 | I1: 是否部省接口同步 | J1: 同步模型说明 | K1: 是否最小集 | L1: 是否支撑生产关键字段
A2: 1 | B2: 资源标识 | C2: res_code | D2: 字符型 | E2: 自动生成 | F2: 是 | G2: 资管系统各资源的唯一标识 | H2: 37150202025645 | I2: 周粒度 | K2: 是 | L2: 是
A3: 2 | B3: 所属省份 | C3: province_id | D3: 关联型 | E3: 自动生成 | F3: 是 | G3: 所属省份信息，关联省份表主键 | H3: 北京市 | I3: 周粒度 | J3: 上报填写所属【省份】行政区域编码；范例：340000，仅部省同步字段 | K3: 否 | L3: 否
A4: 3 | B4: 所属地市 | C4: city_id | D4: 关联型 | E4: 自动生成 | F4: 是 | G4: 所属地市信息，关联地市表主键 | H4: 北京市 | I4: 周粒度 | J4: 上报填写所属【地市】行政区域编码；范例：340100，仅部省同步字段 | K4: 否 | L4: 否
A5: 4 | B5: 所属区县 | C5: county_id | D5: 关联型 | E5: 自动生成 | F5: 是 | G5: 所属区县信息，关联区县表主键 | H5: 大兴区 | I5: 周粒度 | J5: 上报填写所属【区县】行政区域编码，范例：340103，仅部省同步字段 | K5: 否 | L5: 否
A6: 5 | B6: 所属站点 | C6: related_site | D6: 关联型 | E6: 自动生成 | F6: 存在必填 | G6: 自动生成。根据机房所属站点自动生成。当所属机房为资源点时，所属站点可为空。所属机房为机房时必填 | H6: 北京大兴区大白楼工业区 | I6: 周粒度 | J6: 上报填写所属【空间资源】-【站点】的资源标识；范例：3715020203234 | K6: 否 | L6: 是
A7: 6 | B7: 所属机房 | C7: related_room | D7: 关联型 | E7: 手工录入 | F7: 是 | G7: （关联）关联到空间资源中【机房】-资源标识。如为室外设备，可关联至空间资源【位置点（资源点）】-资源标识。 | H7: 北京大兴区大白楼工业区核心机房 | I7: 周粒度 | J7: 上报填写所属【空间资源】-【机房】的资源标识；范例：3715020203234 | K7: 是 | L7: 是
A8: 7 | B8: 设备类型 | C8: device_type | D8: 枚举型 | E8: 自动生成 | F8: 是 | G8: 枚举参考【设备类型&子类】 | H8: 高压直流配电 | I8: 周粒度 | K8: 是 | L8: 否
A9: 8 | B9: 设备子类 | C9: device_subclass | D9: 枚举型 | E9: 手工录入 | F9: 是 | G9: 枚举参考【设备类型&子类】 | H9: 336V直流配电柜 | I9: 周粒度 | K9: 是 | L9: 是
A10: 9 | B10: 设备顺序号 | C10: device_number | D10: 字符型 | E10: 自动生成 | F10: 否 | G10: 站点内相同子类的顺序编号 | H10: 1 | I10: 周粒度 | K10: 是 | L10: 否
A11: 10 | B11: 设备名称 | C11: zh_label | D11: 字符型 | E11: 自动生成 | F11: 是 | G11: 根据集团最新命名规范自动生成 | H11: 北京大兴区大白楼工业区核心机房-高压直流配电-1 | I11: 周粒度 | K11: 是 | L11: 否
A12: 11 | B12: 设备编码 | C12: device_code | D12: 字符型 | E12: 自动生成 | F12: 是 | G12: 根据集团最新命名规范自动生成 | H12: 1301 | I12: 周粒度 | K12: 是 | L12: 否
A13: 12 | B13: 设备型号 | C13: product_name | D13: 枚举型 | E13: 手工录入 | F13: 是 | G13: 参照枚举值在动环设备型号名称中选择。各省新增动环设备型号名称需报备总部后才能执行。 | H13: HVP-336/37A(2000A及以下) | I13: 周粒度 | K13: 是 | L13: 是
A14: 13 | B14: 设备厂家 | C14: vendor_id | D14: 枚举型 | E14: 手工录入 | F14: 是 | G14: 参照枚举值在动环设备厂商名称中选择。各省新增动环设备厂家名称需报备总部后才能执行。 | H14: 中达电通股份有限公司 | I14: 周粒度 | K14: 是 | L14: 是
A15: 14 | B15: 所属系统 | C15: related_system | D15: 关联型 | E15: 手工录入 | F15: 存在必填 | G15: 所属站点的动环专业站点级别为数据中心或通信机楼必填；（关联）关联到【高压直流电源系统】-资源标识 | H15: 北京大兴区大白楼工业区核心机房-高压直流电源系统-1 | I15: 周粒度 | J15: 上报范例：5315020203 | K15: 否 | L15: 是
A16: 15 | B16: 额定容量（A） | C16: reted_capacity | D16: 整数型 | E16: 手工录入 | F16: 是 | G16: 总容量，或系统母排总容量，单位：A | H16: 400 | I16: 周粒度 | K16: 是 | L16: 是
A17: 16 | B17: 输入端口总数（路） | C17: total_input_port | D17: 整数型 | E17: 手工录入 | F17: 是 | G17: 输人端口的总数 | H17: 2 | I17: 周粒度 | K17: 否 | L17: 是
A18: 17 | B18: 输出端口总数（路） | C18: total_onput_port | D18: 整数型 | E18: 手工录入 | F18: 是 | G18: 输出端口的总数 | H18: 40 | I18: 周粒度 | K18: 是 | L18: 是
A19: 18 | B19: 设备串号 | C19: serial_number | D19: 字符型 | E19: 手工录入/自动采集 | F19: 否 | G19: 与资产进行关联的字段，即设备串号，对于OMC北向规范能采集到的，建议采集；无北向规范或北向规范不支持的，不做要求。 | H19: DR100001 | I19: 否 | K19: 否 | L19: 是
A20: 19 | B20: 资产标签号 | C20: assets_no | D20: 字符型 | E20: 手工录入 | F20: 存在必填 | G20: 对应资产管理系统设备资产标签号 | H20: 2226-18601860 | I20: 周粒度 | K20: 是 | L20: 是
A21: 20 | B21: 开始使用时间 | C21: start_time | D21: 日期型 | E21: 手工录入 | F21: 是 | G21: 格式为：YYYY-MM-DD | H21: 2020-07-24 | I21: 周粒度 | K21: 是 | L21: 是
A22: 21 | B22: 预计报废时间 | C22: estimated_retirement_time | D22: 日期型 | E22: 自动生成 | F22: 是 | G22: 格式为：YYYY-MM-DD，参考动力设备维护规程设备更新周期 | H22: 2030-07-24 | I22: 周粒度 | K22: 是 | L22: 否
A23: 22 | B23: 使用状态 | C23: lifecycle_status | D23: 枚举型 | E23: 手工录入 | F23: 是 | G23: 枚举参考lifecycle_status 枚举值：现网、工程、退网、空载 | H23: 现网 | I23: 周粒度 | K23: 是 | L23: 是
A24: 23 | B24: 维护责任人 | C24: maintainor | D24: 字符型 | E24: 手工录入 | F24: 是 | G24: 维护责任人 | H24: 王工 | I24: 周粒度 | K24: 是 | L24: 否
A25: 24 | B25: 数据质量责任人（移动） | C25: qualitor | D25: 字符型 | E25: 手工录入 | F25: 是 | G25: 系统数据录入人员 | H25: 李工 | I25: 周粒度 | K25: 否 | L25: 否
A26: 25 | B26: 项目编码 | C26: project_code | D26: 字符型 | E26: 手工录入 | F26: 否 | G26: 该设备所属工程项目编号 | H26: C1820012 | I26: 否 | K26: 否 | L26: 否
A27: 26 | B27: 任务名称 | C27: long_task_name | D27: 字符型 | E27: 手工录入 | F27: 否 | G27: 该设备所属工程任务名称 | H27: 北京大兴区大白楼工业区核心机房 | I27: 否 | K27: 否 | L27: 否
A28: 27 | B28: 二维码编码 | C28: qr_code_no | D28: 字符型 | E28: 系统生成 | F28: 存在必填 | G28: 按照二维码规范生成二维码编码，用于资源APP现场扫描设备标签。 | H28: 510102019098494 | I28: 周粒度 | K28: 否 | L28: 否
A29: 28 | B29: 动环监控设备名称 | C29: power_device_name | D29: 字符型 | E29: 手工录入/自动采集 | F29: 存在必填 | G29: 填写动环监控系统中的设备名称 | H29: 北京大兴区大白楼工业区核心机房-高压直流配电-1 | I29: 周粒度 | K29: 否 | L29: 否
A30: 29 | B30: 动环监控设备ID | C30: power_device_id | D30: 字符型 | E30: 手工录入/自动采集 | F30: 存在必填 | G30: 填写动环监控系统中的设备ID | H30: 85785766 | I30: 周粒度 | K30: 否 | L30: 否
A31: 30 | B31: 所属系统顺序号 | D31: 关联型 | E31: 手工录入 | F31: 存在必填 | G31: 关联到【高压配电系统】-【系统顺序号】，单选 | H31: 1 | I31: 否 | K31: 是 | L31: 否
A32: 31 | B32: 设备品牌 | D32: 关联型 | E32: 手工录入 | F32: 是 | G32: 设备品牌，只能在动环设备厂家名称梳理表中选择，可自行扩展需报备总部后才能执行 | H32: 施耐德 | I32: 否 | K32: 是 | L32: 否
A33: 32 | B33: 所属机架位置 | D33: 关联型 | E33: 手工录入 | F33: 否 | G33: 关联到【空间资源】-【机架位置】-【机架位置编号】 | I33: 否 | K33: 是 | L33: 否

Sheet 10.低压配电系统
A1: 序号 | B1: 字段 | C1: 英文名称 | D1: 字段类型 | E1: 数据来源 | F1: 是否必填 | G1: 内容说明 | H1: 范例 | I1: 是否部省接口同步 | J1: 同步模型说明 | K1: 是否最小集 | L1: 是否支撑生产关键字段
A2: 1 | B2: 资源标识 | C2: res_code | D2: 字符型 | E2: 自动生成 | F2: 是 | G2: 资管系统各资源的唯一标识 | H2: 37150202025645 | I2: 周粒度 | K2: 是 | L2: 是
A3: 2 | B3: 所属省份 | C3: province_id | D3: 关联型 | E3: 自动生成 | F3: 是 | G3: 所属省份信息，关联省份表主键 | H3: 北京市 | I3: 周粒度 | J3: 上报填写所属【省份】行政区域编码；范例：340000，仅部省同步字段 | K3: 否 | L3: 否
A4: 3 | B4: 所属地市 | C4: city_id | D4: 关联型 | E4: 自动生成 | F4: 是 | G4: 所属地市信息，关联地市表主键 | H4: 北京市 | I4: 周粒度 | J4: 上报填写所属【地市】行政区域编码；范例：340100，仅部省同步字段 | K4: 否 | L4: 否
A5: 4 | B5: 所属区县 | C5: county_id | D5: 关联型 | E5: 自动生成 | F5: 是 | G5: 所属区县信息，关联区县表主键 | H5: 大兴区 | I5: 周粒度 | J5: 上报填写所属【区县】行政区域编码，范例：340103，仅部省同步字段 | K5: 否 | L5: 否
A6: 5 | B6: 所属站点 | C6: related_site | D6: 关联型 | E6: 自动生成 | F6: 存在必填 | G6: 自动生成。根据机房所属站点自动生成。当所属机房为资源点时，所属站点可为空。所属机房为机房时必填 | H6: 北京大兴区大白楼工业区 | I6: 周粒度 | J6: 上报填写所属【空间资源】-【站点】的资源标识；范例：3715020203234 | K6: 否 | L6: 是
A7: 6 | B7: 所属机房 | C7: related_room | D7: 关联型 | E7: 手工录入 | F7: 是 | G7: （关联）关联到空间资源中【机房】-资源标识。如为室外设备，可关联至空间资源【位置点（资源点）】-资源标识。 | H7: 北京大兴区大白楼工业区核心机房 | I7: 周粒度 | J7: 上报填写所属【空间资源】-【机房】的资源标识；范例：3715020203234 | K7: 是 | L7: 是
A8: 7 | B8: 系统类型 | C8: system_type | D8: 枚举型 | E8: 自动生成 | F8: 是 | G8: 枚举参考systemType | H8: 低压配电系统 | I8: 周粒度 | K8: 是 | L8: 否
A9: 8 | B9: 系统顺序号 | C9: system_number | D9: 字符型 | E9: 手工录入 | F9: 否 | G9: 站点内相同子类的顺序编号 | H9: 1 | I9: 周粒度 | K9: 是 | L9: 否
A10: 9 | B10: 系统名称 | C10: zh_label | D10: 字符型 | E10: 手工录入 | F10: 是 | G10: 根据集团最新命名规范填写 | H10: 北京大兴区大白楼工业区核心机房-低压配电系统-1 | I10: 周粒度 | K10: 是 | L10: 是
A11: 10 | B11: 系统编码 | C11: system_code | D11: 字符型 | E11: 自动生成 | F11: 是 | G11: 根据集团最新命名规范自动生成 | H11: 52 | I11: 周粒度 | K11: 是 | L11: 否
A12: 11 | B12: 系统额定容量(KVA) | C12: system_rated_capacity | D12: 整数型 | E12: 手工录入 | F12: 是 | G12: 低压配电系统额定容量，单位：KVA | H12: 1600 | I12: 周粒度 | K12: 否 | L12: 是
A13: 12 | B13: 分段母线数量 | C13: segmented_busbars_number | D13: 整数型 | E13: 手工录入 | F13: 否 | G13: 低压配电系统中分段母线的数量 | H13: 2 | I13: 否 | K13: 是 | L13: 是
A14: 13 | B14: 运行方式 | C14: operation_mode | D14: 枚举型 | E14: 手工录入 | F14: 否 | G14: 枚举参考operationMode 低压配电系统运行方式，例如：1+1、N+1、独立。各省枚举值各省可自行增加 | H14: 1+1 | I14: 否 | K14: 是 | L14: 是
A15: 14 | B15: 使用状态 | C15: lifecycle_status | D15: 枚举型 | E15: 手工录入 | F15: 是 | G15: 枚举参考lifecycle_status 枚举值：现网、工程、退网、空载 | H15: 现网 | I15: 周粒度 | K15: 否 | L15: 是
A16: 15 | B16: 数据质量责任人（移动） | C16: qualitor | D16: 字符型 | E16: 手工录入 | F16: 是 | G16: 系统数据录入人员 | H16: 王工 | I16: 周粒度 | K16: 否 | L16: 否
A17: 16 | B17: 项目编码 | C17: project_code | D17: 字符型 | E17: 手工录入 | F17: 否 | G17: 该设备所属工程项目编号 | H17: C1820012 | I17: 否 | K17: 否 | L17: 否
A18: 17 | B18: 系统内配电柜名称 | D18: 关联型 | E18: 自动生成 | F18: 否 | G18: 系统自动汇总生成，系统内的配电柜设备名称；若有多个配电柜则用英文“;”分开。关联到【低压交流配电】的【设备名称】 | I18: 否 | K18: 是 | L18: 否

Sheet 11.低压交流配电
A1: 序号 | B1: 字段 | C1: 英文名称 | D1: 字段类型 | E1: 数据来源 | F1: 是否必填 | G1: 内容说明 | H1: 范例 | I1: 是否部省接口同步 | J1: 同步模型说明 | K1: 是否最小集 | L1: 是否支撑生产关键字段
A2: 1 | B2: 资源标识 | C2: res_code | D2: 字符型 | E2: 自动生成 | F2: 是 | G2: 资管系统各资源的唯一标识 | H2: 37150202025645 | I2: 周粒度 | K2: 是 | L2: 是
A3: 2 | B3: 所属省份 | C3: province_id | D3: 关联型 | E3: 自动生成 | F3: 是 | G3: 所属省份信息，关联省份表主键 | H3: 浙江省 | I3: 周粒度 | J3: 上报填写所属【省份】行政区域编码；范例：340000，仅部省同步字段 | K3: 否 | L3: 否
A4: 3 | B4: 所属地市 | C4: city_id | D4: 关联型 | E4: 自动生成 | F4: 是 | G4: 所属地市信息，关联地市表主键 | H4: 杭州市 | I4: 周粒度 | J4: 上报填写所属【地市】行政区域编码；范例：340100，仅部省同步字段 | K4: 否 | L4: 否
A5: 4 | B5: 所属区县 | C5: county_id | D5: 关联型 | E5: 自动生成 | F5: 是 | G5: 所属区县信息，关联区县表主键 | H5: 西湖区 | I5: 周粒度 | J5: 上报填写所属【区县】行政区域编码，范例：340103，仅部省同步字段 | K5: 否 | L5: 否
A6: 5 | B6: 所属站点 | C6: related_site | D6: 关联型 | E6: 自动生成 | F6: 存在必填 | G6: 自动生成。根据机房所属站点自动生成。当所属机房为资源点时，所属站点可为空。所属机房为机房时必填 | H6: 杭州白马公寓 | I6: 周粒度 | J6: 上报填写所属【空间资源】-【站点】的资源标识；范例：3715020203234 | K6: 否 | L6: 是
A7: 6 | B7: 所属机房 | C7: related_room | D7: 关联型 | E7: 手工录入 | F7: 是 | G7: （关联）关联到空间资源中【机房】-资源标识。如为室外设备，可关联至空间资源【位置点（资源点）】-资源标识。 | H7: 杭州白马公寓3楼机房 | I7: 周粒度 | J7: 上报填写所属【空间资源】-【机房】的资源标识；范例：3715020203234 | K7: 是 | L7: 是
A8: 7 | B8: 设备类型 | C8: device_type | D8: 枚举型 | E8: 自动生成 | F8: 是 | G8: 枚举参考【设备类型&子类】 | H8: 低压交流配电 | I8: 周粒度 | K8: 是 | L8: 是
A9: 8 | B9: 设备子类 | C9: device_subclass | D9: 枚举型 | E9: 手工录入 | F9: 是 | G9: 枚举参考【设备类型&子类】 | H9: 低压进线柜 | I9: 周粒度 | K9: 是 | L9: 是
A10: 9 | B10: 设备顺序号 | C10: device_number | D10: 字符型 | E10: 自动生成 | F10: 否 | G10: 站点内相同子类的顺序编号 | H10: 1 | I10: 周粒度 | K10: 是 | L10: 否
A11: 10 | B11: 设备名称 | C11: zh_label | D11: 字符型 | E11: 自动生成 | F11: 是 | G11: 根据集团最新命名规范自动生成 | H11: 杭州白马公寓-低压进线柜-1 | I11: 周粒度 | K11: 是 | L11: 是
A12: 11 | B12: 设备编码 | C12: device_code | D12: 字符型 | E12: 自动生成 | F12: 是 | G12: 根据集团最新命名规范自动生成 | H12: 0212 | I12: 周粒度 | K12: 是 | L12: 否
A13: 12 | B13: 设备型号 | C13: product_name | D13: 枚举型 | E13: 手工录入 | F13: 是 | G13: 参照枚举值在动环设备型号名称中选择。各省新增动环设备型号名称需报备总部后才能执行。 | H13: OKKEN | I13: 周粒度 | K13: 是 | L13: 是
A14: 13 | B14: 设备厂家 | C14: vendor_id | D14: 枚举型 | E14: 手工录入 | F14: 是 | G14: 参照枚举值在动环设备厂商名称中选择。各省新增动环设备厂家名称需报备总部后才能执行。 | H14: 博耳（无锡）电力成套有限公司 | I14: 周粒度 | K14: 是 | L14: 是
A15: 14 | B15: 所属系统 | C15: related_system | D15: 关联型 | E15: 手工录入 | F15: 存在必填 | G15: （关联）关联到【UPS系统】或者【开关电源系统】或者【高压直流电源系统】或者【发电系统】或者【低压配电系统】的资源标识。核心站点、骨干站点必填。 | H15: 杭州白马公寓-开关电源系统-1 | I15: 周粒度 | J15: 上报填写所属【UPS系统】或者【开关电源系统】或者【高压直流电源系统】或者【发电系统】或者【低压配电系统】的资源标识；范例：37150202025645 | K15: 否 | L15: 是
A16: 15 | B16: 额定容量(A) | C16: reted_capacity | D16: 整数型 | E16: 手工录入 | F16: 是 | G16: 设备输出额定容量，默认单位为A。独立防雷箱和电容补偿柜填写输入开关容量 | H16: 3200 | I16: 周粒度 | K16: 是 | L16: 是
A17: 16 | B17: 输入端口数（路） | C17: total_input_port | D17: 整数型 | E17: 手工录入 | F17: 存在必填 | G17: 枚举参考totalInputPort 枚举值：1、2。如1路断路器输入为1，ATS输入端口为2，数据中心及通信机楼必填 | H17: 1 | I17: 周粒度 | K17: 是 | L17: 是
